Workbook

Sheet ALL DOOR
A1: DOOR TAG | B1: BUILDINGN AREA | C1: ROOM NO. | D1: DOOR LOCATION | E1: INTERIOR/EXTERIOR | F1: QUANTITY | G1: WALL TYPE | H1: THROAT THICKNESS | I1: EXCLUDE REASON | J1: FIRE RATING | K1: LEAF COUNT | L1: DOOR TYPE | M1: DOOR WIDTH | N1: DOOR HEIGHT | O1: THICKNESS | P1: DOOR WIDTH (MM) | Q1: DOOR HEIGHT (MM) | R1: DOOR MATERIAL | S1: DOOR FINISH | T1: GLAZING TYPE | U1: FRAME TYPE | V1: FRAME MATERIAL | W1: FRAME FINISH | X1: HARDWARE SET | Y1: HW SET | Z1: HARDWARE PREP | AA1: HARDWARE ON DOOR | AB1: CARD READER | AC1: KEY PAD | AD1: AUTO OPERATOR | AE1: PRIVACY SET | AF1: KEYED LOCK | AG1: PUSH PLATE | AH1: ANTI- BARRICADE | AI1: KICK PLATE | AJ1: FRAME PROTECTION | AK1: DOOR CLOSER | AL1: COMMENTS
A2: 1109 | B2: LEVEL 01 | C2: 1109 | D2: CAFETERIA | E2: INTERIOR | F2: 1 | G2: *FP | H2: 4 3/4" | J2: 45 MIN. | K2: 2 | L2: C1 | M2: 2*3'-0" | N2: 7'-0" | O2: 1 3/4" | P2: 2*915 | Q2: 2135 | R2: HOLLOW METAL | S2: PT | T2: FIRE-RATED | U2: FR1 | V2: HM | W2: PT | X2: STOREROOM LOCKSET | Y2: AD09a | Z2: Continuous Hinge + Lock | AA2: HM | AB2: - | AC2: - | AD2: Y | AE2: - | AF2: Y | AG2: - | AH2: - | AI2: - | AJ2: - | AL2: FREE EGRESS AT ALL TIMES, NORTH DOOR LEAF INACTIVE WITH FLUSH BOLT AT THE HEAD
A3: 1111 | B3: LEVEL 01 | C3: 1111 | D3: FOOD SERVICES | E3: INTERIOR | F3: 1 | G3: P1.1 | H3: 4 7/8" | K3: 1 | L3: A1 | M3: 2'-8" | N3: 7'-0" | O3: 1 3/4" | P3: 810 | Q3: 2135 | R3: HOLLOW METAL | S3: PT | T3: - | U3: FR1 | V3: HM | W3: PT | X3: STOREROOM LOCKSET | Y3: SE02a.W | Z3: Hinges + Lock + Closer | AA3: HM
A4: 2701 | B4: LEVEL 02 | C4: 2701 | D4: CHECK-IN | E4: INTERIOR | F4: 1 | G4: P1.0 | H4: 4 7/8" | J4: - | K4: 1 | L4: A3 | M4: 3'-0" | N4: 7'-0" | O4: 1 3/4" | P4: 915 | Q4: 2135 | R4: WOOD, SOLIDE CORE | S4: PLAM | T4: TEMP/LAM | U4: FR1 | V4: HM | W4: PT | X4: STOREROOM LOCKSET | Y4: CA01 | Z4: Continuous HInge + Lock + Closer | AA4: WOOD | AB4: Y | AC4: - | AD4: - | AE4: - | AF4: - | AG4: - | AH4: - | AI4: - | AJ4: -
A5: 2701A | B5: LEVEL 02 | C5: 2701 | D5: CHECK-IN | E5: INTERIOR | F5: 1 | G5: P1.0 | H5: 4 7/8" | J5: - | K5: 1 | L5: A3 | M5: 3'-0" | N5: 7'-0" | O5: 1 3/4" | P5: 915 | Q5: 2135 | R5: WOOD, SOLIDE CORE | S5: PLAM | T5: TEMP/LAM | U5: FR1 | V5: HM | W5: PT | X5: STOREROOM LOCKSET | Y5: CA01 | Z5: Continuous HInge + Lock + Closer | AA5: WOOD | AB5: Y | AC5: - | AD5: - | AE5: - | AF5: - | AG5: - | AH5: - | AI5: - | AJ5: -
A6: 2704 | B6: LEVEL 02 | C6: 2704 | D6: WC - PUBLIC | E6: INTERIOR | F6: 1 | G6: P1.1 | H6: 4 7/8" | J6: - | K6: 1 | L6: A1 | M6: 3'-6" | N6: 7'-0" | O6: 1 3/4" | P6: 1070 | Q6: 2134 | R6: WOOD, SOLIDE CORE | S6: PLAM | T6: - | U6: FR2 | V6: HM | W6: PT | X6: STOREROOM LOCKSET | Y6: WE01a | Z6: Continuous Hinge + Lock | AA6: WOOD | AB6: - | AC6: - | AD6: Y | AE6: Y | AF6: - | AG6: - | AH6: Y | AI6: - | AJ6: -
A7: 2706 | B7: LEVEL 02 | C7: 2706 | D7: SECURITY BOOTH | E7: INTERIOR | F7: 1 | G7: P1.0 | H7: 4 7/8" | J7: - | K7: 1 | L7: A3 | M7: 3'-0" | N7: 7'-0" | O7: 1 3/4" | P7: 915 | Q7: 2135 | R7: WOOD, SOLIDE CORE | S7: PLAM | T7: TEMP/LAM | U7: FR1 | V7: HM | W7: PT | X7: STOREROOM LOCKSET | Y7: CA02 | Z7: Continuous HInge + Lock + Closer | AA7: WOOD | AB7: Y | AC7: - | AD7: - | AE7: - | AF7: - | AG7: - | AH7: - | AI7: - | AJ7: - | AL7: GLASS TO RECEIVE FILM: CASPER CLOAKING TECHNOLOGY FILM. SEE SPECIFICATIONS
A8: 2708 | B8: LEVEL 02 | C8: CORR-2708 | D8: CORRIDOR | E8: INTERIOR | F8: 1 | G8: P1.0 | H8: 4 7/8" | J8: - | K8: 2 | L8: C3 | M8: 2*3'-6" | N8: 7'-0" | O8: 1 3/4" | P8: 2*1068 | Q8: 2135 | R8: WOOD, SOLIDE CORE | S8: ACROVYN | T8: TEMP/LAM | U8: FR1 | V8: HM | W8: PT | X8: EXIT DEVICE | Y8: AD01b | Z8: Continuous Hinge + Exit Device | AA8: WOOD | AB8: Y | AC8: - | AD8: Y | AE8: - | AF8: - | AG8: - | AH8: - | AI8: - | AJ8: - | AL8: BUZZ ENTRY FROM CHECK-IN DESK
A9: 2714 | B9: LEVEL 02 | C9: 2714 | D9: CARE TEAM STATION | E9: INTERIOR | F9: 1 | G9: - | H9: - | J9: - | K9: 1 | L9: A7 | M9: 2'-8" | N9: 7'-0" | O9: 1 3/4" | P9: 813 | Q9: 2134 | R9: WOOD, SOLIDE CORE | S9: PLAM | T9: - | U9: FR5 | W9: PT | Y9: BD01 | Z9: Barn Door Kit + Lock + Flush Pull | AA9: WOOD | AB9: - | AC9: - | AD9: - | AE9: - | AF9: - | AG9: - | AH9: - | AI9: - | AJ9: -
A10: 2718 | B10: LEVEL 02 | C10: CORR-2718 | D10: CORRIDOR | E10: INTERIOR | F10: 1 | I10: Aluminum | J10: - | L10: C4 | M10: 2'-8" | N10: 7'-0" | P10: 2135 | Q10: 2135 | R10: AL | S10: ANOD | T10: TEMP/LAM | U10: FR1 | V10: AL | W10: ANOD | Y10: AD02a | AB10: - | AC10: - | AD10: Y | AE10: - | AF10: - | AG10: Y | AH10: - | AI10: - | AJ10: -
A11: 2720 | B11: LEVEL 02 | C11: 2720 | D11: VESTIBULE AMBULANCE | E11: EXTERIOR | F11: 1 | I11: Aluminum | J11: - | L11: C4 | M11: 3'-7" | N11: 7'-3" | P11: 2185 | Q11: 2160 | R11: AL | S11: ANOD | T11: TEMP/LAM | U11: - | V11: AL | W11: ANOD | Y11: AD03a | AB11: Y | AC11: Y | AD11: Y | AE11: - | AF11: - | AG11: - | AH11: - | AI11: - | AJ11: -
A12: 2721 | B12: LEVEL 02 | C12: 2721 | D12: EXAM 1 | E12: INTERIOR | F12: 1 | I12: Aluminum | J12: - | L12: D2 | M12: 3*2'-5" | N12: 7'-6" | P12: 2133 | Q12: 2279 | R12: AL | S12: ANOD | T12: TEMP/LAM | U12: FR1 | V12: AL | W12: ANOD | Y12: NOTE#2 | AB12: - | AC12: - | AD12: - | AE12: - | AF12: - | AG12: - | AH12: - | AI12: - | AJ12: - | AL12: ALL HARDWARE BY DOOR SUPPLIER. ANY REQUIRED CYLINDER TO MATCH CLIENT KEY SYSTEM.
A13: 2723 | B13: LEVEL 02 | C13: 2723 | D13: EXAM 2 | E13: INTERIOR | F13: 1 | I13: Aluminum | J13: - | L13: D2 | M13: 3*2'-5" | N13: 7'-6" | P13: 2133 | Q13: 2279 | R13: AL | S13: ANOD | T13: TEMP/LAM | U13: FR1 | V13: AL | W13: ANOD | Y13: NOTE#2 | AB13: - | AC13: - | AD13: - | AE13: - | AF13: - | AG13: - | AH13: - | AI13: - | AJ13: - | AL13: ALL HARDWARE BY DOOR SUPPLIER. ANY REQUIRED CYLINDER TO MATCH CLIENT KEY SYSTEM.
A14: 2725 | B14: LEVEL 02 | C14: 2725 | D14: EXAM 3 | E14: INTERIOR | F14: 1 | I14: Aluminum | J14: - | L14: D2 | M14: 3*2'-5" | N14: 7'-6" | P14: 2133 | Q14: 2279 | R14: AL | S14: ANOD | T14: TEMP/LAM | U14: FR1 | V14: AL | W14: ANOD | Y14: NOTE#2 | AB14: - | AC14: - | AD14: - | AE14: - | AF14: - | AG14: - | AH14: - | AI14: - | AJ14: - | AL14: ALL HARDWARE BY DOOR SUPPLIER. ANY REQUIRED CYLINDER TO MATCH CLIENT KEY SYSTEM.
A15: 2727 | B15: LEVEL 02 | C15: 2727 | D15: EXAM AIR | E15: INTERIOR | F15: 1 | G15: P2.0S | H15: 7 1/4" | J15: - | K15: 2 | L15: B3 | M15: 1'-4", 3'-6" | N15: 7'-0" | O15: 1 3/4" | P15: 404, 1071 | Q15: 2135 | R15: WOOD, SOLIDE CORE | S15: PLAM | T15: TEMP/LAM | U15: FR1 | V15: HM | W15: PT | Y15: PA01 | Z15: Continuous Hinge + Pull + Closer | AA15: WOOD | AB15: - | AC15: - | AD15: - | AE15: - | AF15: - | AG15: - | AH15: - | AI15: - | AJ15: -
A16: 2727A | B16: LEVEL 02 | C16: 2727A | D16: ANTEROOM | E16: INTERIOR | F16: 1 | G16: P2.0 | H16: 7 1/4" | J16: - | K16: 1 | L16: A2 | M16: 3'-0" | N16: 7'-0" | O16: 1 3/4" | P16: 915 | Q16: 2135 | R16: WOOD, SOLIDE CORE | S16: PLAM | T16: TEMP/LAM | U16: FR1 | V16: HM | W16: PT | X16: PASSAGE SET | Y16: AD07b | Z16: Continuous Hinge + Lock | AA16: WOOD | AB16: - | AC16: - | AD16: Y | AE16: - | AF16: - | AG16: - | AH16: - | AI16: - | AJ16: -
A17: 2727B | B17: LEVEL 02 | C17: 2727B | D17: ENSUITE | E17: INTERIOR | F17: 1 | G17: P2.0 | H17: 7 1/4" | J17: - | K17: 1 | L17: A1 | M17: 3'-6" | N17: 7'-0" | O17: 1 3/4" | P17: 1070 | Q17: 2134 | R17: WOOD, SOLIDE CORE | S17: PLAM | T17: - | U17: FR7 | V17: HM | W17: PT | X17: PASSAGE SET | Y17: WA01 | Z17: Continuous HInge + Lock | AA17: WOOD | AB17: - | AC17: - | AD17: - | AE17: - | AF17: - | AG17: - | AH17: Y | AI17: - | AJ17: - | AL17: NO HEADER FRAME (TO ALLOW PATIENT LIFT TRAVEL)
A18: 2727C | B18: LEVEL 02 | C18: 2727 | D18: EXAM AIR | E18: INTERIOR | F18: 1 | G18: P2.0 | H18: 7 1/4" | J18: - | K18: 1 | L18: A3 | M18: 3'-0" | N18: 7'-0" | O18: 1 3/4" | P18: 915 | Q18: 2135 | R18: WOOD, SOLIDE CORE | S18: PLAM | T18: TEMP/LAM | U18: FR1 | V18: HM | W18: PT | X18: PASSAGE SET | Y18: AD07b | Z18: Continuous Hinge + Lock | AA18: WOOD | AB18: - | AC18: - | AD18: Y | AE18: - | AF18: - | AG18: - | AH18: - | AI18: - | AJ18: -
A19: 2729 | B19: LEVEL 02 | C19: 2729 | D19: ANTEROOM | E19: INTERIOR | F19: 1 | G19: P2.0 | H19: 7 1/4" | J19: - | K19: 1 | L19: A2 | M19: 3'-0" | N19: 7'-0" | O19: 1 3/4" | P19: 915 | Q19: 2135 | R19: WOOD, SOLIDE CORE | S19: PLAM | T19: TEMP/LAM | U19: FR1 | V19: HM | W19: PT | X19: PASSAGE SET | Y19: AD07b | Z19: Continuous Hinge + Lock | AA19: WOOD | AB19: - | AC19: - | AD19: Y | AE19: - | AF19: - | AG19: - | AH19: - | AI19: - | AJ19: -
A20: 2731 | B20: LEVEL 02 | C20: 2731 | D20: RESUSCITATION ROOM | E20: INTERIOR | F20: 1 | I20: Aluminum | J20: - | L20: D3 | M20: 4*1'-10" | N20: 7'-8" | P20: 2700 | Q20: 2335 | R20: AL | S20: ANOD | T20: TEMP/LAM | U20: FR1 | V20: AL | W20: ANOD | Y20: NOTE#2 | AB20: - | AC20: - | AD20: Y | AE20: - | AF20: - | AG20: - | AH20: - | AI20: - | AJ20: - | AL20: ALL HARDWARE BY DOOR SUPPLIER. ANY REQUIRED CYLINDER TO MATCH CLIENT KEY SYSTEM.
A21: 2731A | B21: LEVEL 02 | C21: 2729 | D21: ANTEROOM | E21: INTERIOR | F21: 1 | G21: P2.0 | H21: 7 1/4" | J21: - | K21: 1 | L21: A3 | M21: 3'-0" | N21: 7'-0" | O21: 1 3/4" | P21: 915 | Q21: 2135 | R21: WOOD, SOLIDE CORE | S21: PLAM | T21: TEMP/LAM | U21: FR1 | V21: HM | W21: PT | X21: PASSAGE SET | Y21: AD07b | Z21: Continuous Hinge + Lock | AA21: WOOD | AB21: - | AC21: - | AD21: Y | AE21: - | AF21: - | AG21: - | AH21: - | AI21: - | AJ21: -
A22: 2733 | B22: LEVEL 02 | C22: 2733 | D22: MEDICATION | E22: INTERIOR | F22: 1 | G22: P1.0 | H22: 4 7/8" | J22: - | K22: 1 | L22: A3 | M22: 3'-6" | N22: 7'-0" | O22: 1 3/4" | P22: 1070 | Q22: 2135 | R22: WOOD, SOLIDE CORE | S22: PLAM | T22: TEMP/LAM | U22: FR1 | V22: HM | W22: PT | X22: STOREROOM LOCKSET | Y22: CA01.W | Z22: Continuous HInge + Lock + Closer | AA22: WOOD | AB22: Y | AC22: Y | AD22: - | AE22: - | AF22: - | AG22: - | AH22: - | AI22: Y | AJ22: -
A23: 2734 | B23: LEVEL 02 | C23: 2734 | D23: WC - STAFF | E23: INTERIOR | F23: 1 | G23: P2.2 | H23: 8 1/2" | J23: - | K23: 1 | L23: A1 | M23: 3'-0" | N23: 7'-0" | O23: 1 3/4" | P23: 915 | Q23: 2134 | R23: WOOD, SOLIDE CORE | S23: PLAM | T23: - | U23: FR2 | V23: HM | W23: PT | X23: PRIVACY LOCKSET | Y23: WA02 | Z23: Continuous Hinge + Lock | AA23: WOOD | AB23: - | AC23: - | AD23: - | AE23: Y | AF23: - | AG23: - | AH23: Y | AI23: - | AJ23: -
A24: 2740 | B24: LEVEL 02 | C24: CORR-2740 | D24: CORRIDOR | E24: INTERIOR | F24: 1 | G24: P2.0 | H24: 7 1/4" | J24: 90 MIN. | K24: 2 | L24: C2 | M24: 2*3'-6" | N24: 7'-0" | O24: 1 3/4" | P24: 2135 | Q24: 2135 | R24: HOLLOW METAL | S24: PT | T24: - | U24: FR6 | V24: HM | W24: PT | X24: EXIT DEVICE | Y24: AD05e | Z24: Continuous Hinge + Exit Device | AA24: HM | AB24: Y | AC24: - | AD24: Y | AE24: - | AF24: - | AG24: - | AH24: - | AI24: - | AJ24: - | AL24: FREE EGRESS VIA PANIC BAR - 15 SECONDS DELAYED EGRESS
A25: 2742 | B25: LEVEL 02 | C25: 2742 | D25: QUIET INTERVIEW ROOM | E25: INTERIOR | F25: 1 | G25: P2.0 | H25: 7 1/4" | J25: - | K25: 1 | L25: A2 | M25: 3'-0" | N25: 7'-0" | O25: 1 3/4" | P25: 915 | Q25: 2134 | R25: WOOD, SOLIDE CORE | S25: PLAM | T25: TEMP/LAM | U25: FR2 | V25: HM | W25: PT | X25: CLASSROOM LOCKSET | Y25: SE01 | Z25: Continuous Hinge + Lock | AA25: WOOD | AB25: - | AC25: - | AD25: - | AE25: - | AF25: - | AG25: - | AH25: Y | AI25: - | AJ25: -
A26: 2742A | B26: LEVEL 02 | C26: 2742 | D26: QUIET INTERVIEW ROOM | E26: INTERIOR | F26: 1 | G26: P2.0 | H26: 7 1/4" | J26: - | K26: 1 | L26: A2 | M26: 3'-0" | N26: 7'-0" | O26: 1 3/4" | P26: 915 | Q26: 2134 | R26: WOOD, SOLIDE CORE | S26: PLAM | T26: TEMP/LAM | U26: FR2 | V26: HM | W26: PT | X26: CLASSROOM LOCKSET | Y26: SE01 | Z26: Continuous Hinge + Lock | AA26: WOOD | AB26: - | AC26: - | AD26: - | AE26: - | AF26: - | AG26: - | AH26: Y | AI26: - | AJ26: -
A27: 2743 | B27: LEVEL 02 | C27: 2743 | D27: WC/SHOWER - PATIENT | E27: INTERIOR | F27: 1 | G27: P2.0 | H27: 7 1/4" | J27: - | K27: 1 | L27: A1 | M27: 3'-6" | N27: 7'-0" | O27: 1 3/4" | P27: 1070 | Q27: 2134 | R27: WOOD, SOLIDE CORE | S27: PLAM | T27: - | U27: FR2 | V27: HM | W27: PT | X27: STOREROOM LOCKSET | Y27: WE01a | Z27: Continuous Hinge + Lock | AA27: WOOD | AB27: - | AC27: - | AD27: Y | AE27: Y | AF27: - | AG27: - | AH27: Y | AI27: - | AJ27: -
A28: 2745 | B28: LEVEL 02 | C28: 2745 | D28: SOILED UTILITY | E28: INTERIOR | F28: 1 | G28: P2.0 | H28: 7 1/4" | J28: - | K28: 1 | L28: A3 | M28: 3'-0" | N28: 7'-0" | O28: 1 3/4" | P28: 915 | Q28: 2135 | R28: WOOD, SOLIDE CORE | S28: PLAM | T28: TEMP/LAM | U28: FR1 | V28: HM | W28: PT | X28: STOREROOM LOCKSET | Y28: CA01 | Z28: Continuous HInge + Lock + Closer | AA28: WOOD | AB28: Y | AC28: - | AD28: - | AE28: - | AF28: - | AG28: - | AH28: - | AI28: Y | AJ28: -
A29: 2746 | B29: LEVEL 02 | C29: 2746 | D29: EXAM 3.2 | E29: INTERIOR | F29: 1 | I29: Aluminum | J29: - | L29: D2 | M29: 3*2'-5" | N29: 7'-6" | P29: 2133 | Q29: 2279 | R29: AL | S29: ANOD | T29: TEMP/LAM | U29: FR1 | V29: AL | W29: ANOD | Y29: NOTE#2 | AB29: - | AC29: - | AD29: - | AE29: - | AF29: - | AG29: - | AH29: - | AI29: - | AJ29: - | AL29: ALL HARDWARE BY DOOR SUPPLIER. ANY REQUIRED CYLINDER TO MATCH CLIENT KEY SYSTEM.
A30: 2754 | B30: LEVEL 02 | C30: CORR-2754 | D30: CORRIDOR | E30: INTERIOR | F30: 1 | G30: P2.0 | H30: 7 1/4" | J30: - | K30: 2 | L30: C7 | M30: 2*3'-6" | N30: 7'-0" | O30: 1 3/4" | P30: 2135 | Q30: 2135 | R30: WOOD, SOLIDE CORE | S30: ACROVYN | T30: TEMP/LAM | U30: FR1 | V30: HM | W30: PT | X30: EXIT DEVICE | Y30: AD06a | Z30: Continuous Hinge + Exit Device | AA30: WOOD | AB30: Y | AC30: - | AD30: Y | AE30: - | AF30: - | AG30: - | AH30: - | AI30: - | AJ30: -
A31: 2756 | B31: LEVEL 02 | C31: 2756 | D31: WC STAFF | E31: INTERIOR | F31: 1 | G31: P1.0 | H31: 4 7/8" | J31: - | K31: 1 | L31: A1 | M31: 3'-0" | N31: 7'-0" | O31: 1 3/4" | P31: 915 | Q31: 2134 | R31: WOOD, SOLIDE CORE | S31: PLAM | T31: - | U31: FR2 | V31: HM | W31: PT | X31: PRIVACY LOCKSET | Y31: WA02 | Z31: Continuous Hinge + Lock | AA31: WOOD | AB31: - | AC31: - | AD31: - | AE31: Y | AF31: - | AG31: - | AH31: Y | AI31: - | AJ31: -
A32: 2758 | B32: LEVEL 02 | C32: 2758 | D32: HOUSEKEEPING | E32: INTERIOR | F32: 1 | G32: P2.0 | H32: 7 1/4" | J32: 0 HR | K32: 1 | L32: A2 | M32: 3'-0" | N32: 7'-0" | O32: 1 3/4" | P32: 915 | Q32: 2135 | R32: HOLLOW METAL | S32: PT | T32: TEMP/LAM | U32: FR1 | V32: HM | W32: PT | X32: STOREROOM LOCKSET | Y32: SE02a | Z32: Hinges + Lock + Closer | AA32: HM | AB32: - | AC32: - | AD32: - | AF32: Y | AG32: - | AH32: - | AI32: Y | AJ32: -
A33: 2762 | B33: LEVEL 02 | C33: 2762 | D33: WC PATIENT | E33: INTERIOR | F33: 1 | G33: P2.0 | H33: 7 1/4" | J33: - | K33: 1 | L33: A1 | M33: 3'-6" | N33: 7'-0" | O33: 1 3/4" | P33: 1070 | Q33: 2134 | R33: WOOD, SOLIDE CORE | S33: PLAM | T33: - | U33: FR2 | V33: HM | W33: PT | X33: STOREROOM LOCKSET | Y33: WE01a | Z33: Continuous Hinge + Lock | AA33: WOOD | AB33: - | AC33: - | AD33: Y | AE33: Y | AF33: - | AG33: - | AH33: Y | AI33: - | AJ33: -
A34: 2764 | B34: LEVEL 02 | C34: 2764 | D34: MEDICATION | E34: INTERIOR | F34: 1 | G34: P2.0 | H34: 7 1/4" | J34: - | K34: 1 | L34: A3 | M34: 3'-6" | N34: 7'-0" | O34: 1 3/4" | P34: 1070 | Q34: 2135 | R34: WOOD, SOLIDE CORE | S34: PLAM | T34: TEMP/LAM | U34: FR1 | V34: HM | W34: PT | X34: STOREROOM LOCKSET | Y34: CA01.W | Z34: Continuous HInge + Lock + Closer | AA34: WOOD | AB34: Y | AC34: Y | AD34: - | AE34: - | AF34: - | AG34: - | AH34: - | AI34: Y | AJ34: -
A35: 2767 | B35: LEVEL 02 | C35: 2767 | D35: LARGE EXAM ROOM | E35: INTERIOR | F35: 1 | G35: P2.0 | H35: 7 1/4" | J35: - | K35: 2 | L35: B1 | M35: 1'-0", 3'-6" | N35: 7'-0" | O35: 1 3/4" | P35: 1220 | Q35: 2135 | R35: WOOD, SOLIDE CORE | S35: PLAM | T35: - | U35: FR1 | V35: HM | W35: PT | X35: CLASSROOM LOCKSET | Y35: SE03 | Z35: Continuous Hinge + Lock | AA35: WOOD | AB35: - | AC35: - | AD35: - | AE35: - | AF35: - | AG35: - | AH35: - | AI35: - | AJ35: -
A36: 2768 | B36: LEVEL 02 | C36: CORR-2768 | D36: CORRIDOR | E36: INTERIOR | F36: 1 | G36: P2.0 | H36: 7 1/4" | J36: - | K36: 1 | L36: A2 | M36: 3'-6" | N36: 7'-0" | O36: 1 3/4" | P36: 1070 | Q36: 2135 | R36: WOOD, SOLIDE CORE | S36: ACROVYN | T36: TEMP/LAM | U36: FR1 | V36: HM | W36: PT | X36: ELECTROMECHANICAL LOCK | Y36: CA03 | Z36: Continuous Hinge + Electromechnical Lock | AA36: WOOD | AB36: Y | AC36: - | AD36: - | AE36: - | AF36: - | AG36: - | AH36: - | AI36: - | AJ36: -
A37: 2769 | B37: LEVEL 02 | C37: 2769 | D37: EXAM 2.2 | E37: INTERIOR | F37: 1 | I37: Aluminum | J37: - | L37: D2 | M37: 3*2'-5" | N37: 7'-6" | P37: 2133 | Q37: 2279 | R37: AL | S37: ANOD | T37: TEMP/LAM | U37: FR1 | V37: AL | W37: ANOD | Y37: NOTE#2 | AB37: - | AC37: - | AD37: - | AE37: - | AF37: - | AG37: - | AH37: - | AI37: - | AJ37: - | AL37: ALL HARDWARE BY DOOR SUPPLIER. ANY REQUIRED CYLINDER TO MATCH CLIENT KEY SYSTEM.
A38: 2771 | B38: LEVEL 02 | C38: 2771 | D38: EXAM 2.1 | E38: INTERIOR | F38: 1 | I38: Aluminum | J38: - | L38: D2 | M38: 3*2'-5" | N38: 7'-6" | P38: 2133 | Q38: 2279 | R38: AL | S38: ANOD | T38: TEMP/LAM | U38: FR1 | V38: AL | W38: ANOD | Y38: NOTE#2 | AB38: - | AC38: - | AD38: - | AE38: - | AF38: - | AG38: - | AH38: - | AI38: - | AJ38: - | AL38: ALL HARDWARE BY DOOR SUPPLIER. ANY REQUIRED CYLINDER TO MATCH CLIENT KEY SYSTEM.
A39: GATE-01 | B39: LEVEL 02 | E39: EXTERIOR | F39: 1 | I39: Fence Gate | L39: A6 | M39: 3'-8" | N39: 7'-6" | P39: 1156 | Q39: 2300 | T39: - | Y39: GA01 | AL39: CHAINLINK FENCE GATE TO AHU.
A40: E1109A | B40: LEVEL 01 | C40: 1109 | D40: CAFETERIA | E40: INTERIOR | F40: 1 | I40: Existing | J40: EXISTING | L40: EXISTING | R40: EXISTING | S40: EXISTING | W40: EXISTING | Y40: NOTE#1 | AB40: EXISTING | AD40: EXISTING | AF40: EXISTING | AI40: EXISTING | AK40: EXISTING | AL40: EXISTING HARDWARE TO REMAIN; NO CHANGE
...

Sheet HARDWARE
A1: HARDWARE
A3: HARDWARE BOM
A4: S/N | B4: Item | C4: Manufacturer | D4: Description | E4: Finish | F4: Total Qty | G4: Rate | H4: =A111 -> AD01b | K4: =A112 -> - | N4: =A113 -> - | Q4: =A114 -> AD05e | T4: =A115 -> AD06a | W4: =A116 -> AD07b | Z4: =A117 -> AD08b | AC4: =A118 -> AD09a | AF4: =A119 -> BD01 | AI4: =A120 -> CA01 | AL4: =A121 -> CA01.W | AO4: =A122 -> CA02 | AR4: =A123 -> CA03 | AU4: =A124 -> - | AX4: =A125 -> PA01 | BA4: =A126 -> SE01 | BD4: =A127 -> SE02a | BG4: =A128 -> SE02a.W | BJ4: =A129 -> SE03 | BM4: =A130 -> SE04 | BP4: =A131 -> - | BS4: =A132 -> WA01 | BV4: =A133 -> WA02 | BY4: =A134 -> WE01a | CB4: =A135 -> SE05 | CE4: =A136 -> 0 | CH4: =A137 -> 0 | CK4: =A138 -> 0 | CN4: =A139 -> 0 | CQ4: =A140 -> 0 | CT4: =A141 -> 0 | CW4: =A142 -> 0 | CZ4: =A143 -> 0 | DC4: =A144 -> 0 | DF4: =A145 -> 0 | DI4: =A146 -> 0 | DL4: =A147 -> 0 | DO4: =A148 -> 0 | DR4: =A149 -> 0 | DU4: =A150 -> 0 | DX4: =A151 -> 0 | EA4: =A152 -> 0 | ED4: =A153 -> 0 | EG4: =A154 -> 0 | EJ4: =A155 -> 0 | EM4: =A156 -> 0
H5: Qty | I5: Total Q | J5: Amount | K5: Qty | L5: Total Q | M5: Amount | N5: Qty | O5: Total Q | P5: Amount | Q5: Qty | R5: Total Q | S5: Amount | T5: Qty | U5: Total Q | V5: Amount | W5: Qty | X5: Total Q | Y5: Amount | Z5: Qty | AA5: Total Q | AB5: Amount | AC5: Qty | AD5: Total Q | AE5: Amount | AF5: Qty | AG5: Total Q | AH5: Amount | AI5: Qty | AJ5: Total Q | AK5: Amount | AL5: Qty | AM5: Total Q | AN5: Amount | AO5: Qty | AP5: Total Q | AQ5: Amount | AR5: Qty | AS5: Total Q | AT5: Amount | AU5: Qty | AV5: Total Q | AW5: Amount | AX5: Qty | AY5: Total Q | AZ5: Amount | BA5: Qty | BB5: Total Q | BC5: Amount | BD5: Qty | BE5: Total Q | BF5: Amount | BG5: Qty | BH5: Total Q | BI5: Amount | BJ5: Qty | BK5: Total Q | BL5: Amount | BM5: Qty | BN5: Total Q | BO5: Amount | BP5: Qty | BQ5: Total Q | BR5: Amount | BS5: Qty | BT5: Total Q | BU5: Amount | BV5: Qty | BW5: Total Q | BX5: Amount | BY5: Qty | BZ5: Total Q | CA5: Amount | CB5: Qty | CC5: Total Q | CD5: Amount | CE5: Qty | CF5: Total Q | CG5: Amount | CH5: Qty | CI5: Total Q | CJ5: Amount | CK5: Qty | CL5: Total Q | CM5: Amount | CN5: Qty | CO5: Total Q | CP5: Amount | CQ5: Qty | CR5: Total Q | CS5: Amount | CT5: Qty | CU5: Total Q | CV5: Amount | CW5: Qty | CX5: Total Q | CY5: Amount | CZ5: Qty | DA5: Total Q | DB5: Amount | DC5: Qty | DD5: Total Q | DE5: Amount | DF5: Qty | DG5: Total Q | DH5: Amount | DI5: Qty | DJ5: Total Q | DK5: Amount | DL5: Qty | DM5: Total Q | DN5: Amount | DO5: Qty | DP5: Total Q | DQ5: Amount | DR5: Qty | DS5: Total Q | DT5: Amount | DU5: Qty | DV5: Total Q | DW5: Amount | DX5: Qty | DY5: Total Q | DZ5: Amount | EA5: Qty | EB5: Total Q | EC5: Amount | ED5: Qty | EE5: Total Q | EF5: Amount | EG5: Qty | EH5: Total Q | EI5: Amount | EJ5: Qty | EK5: Total Q | EL5: Amount | EM5: Qty | EN5: Total Q | EO5: Amount
A6: 1 | B6: Continuous Hinge | C6: McKinney | D6: (83") FM-HD1-SER12 x length | E6: CA | F6: =SUM(I6,L6,O6,BN6,R6,U6,X6,AA6,BZ6,CC6,CF6,AD6,AG6,AJ6,AM6,AP6,AS6,AV6,AY6,BB6,BE6,BH6,BK6,BQ6,BT6,BW6,CI6,CL6,CO6,CR6,CU6,CX6,DA6,DD6,DG6,DJ6,DM6,DP6,DS6,DV6,DY6,EB6,EE6,EH6,EK6,EN6) -> 11 | H6: 2 | I6: =H6*$B$111 -> 2 | J6: =$G6*H6 -> 0 | L6: =K6*$B$112 -> 0 | M6: =$G6*K6 -> 0 | O6: =N6*$B$113 -> 0 | P6: =$G6*N6 -> 0 | Q6: 2 | R6: =Q6*$B$114 -> 2 | S6: =$G6*Q6 -> 0 | T6: 2 | U6: =T6*$B$115 -> 2 | V6: =$G6*T6 -> 0 | W6: 1 | X6: =W6*$B$116 -> 4 | Y6: =$G6*W6 -> 0 | AA6: =Z6*$B$117 -> 0 | AB6: =$G6*Z6 -> 0 | AC6: 1 | AD6: =AC6*$B$118 -> 1 | AE6: =$G6*AC6 -> 0 | AG6: =AF6*$B$119 -> 0 | AH6: =$G6*AF6 -> 0 | AJ6: =AI6*$B$120 -> 0 | AK6: =$G6*AI6 -> 0 | AM6: =AL6*$B$121 -> 0 | AN6: =$G6*AL6 -> 0 | AP6: =AO6*$B$122 -> 0 | AQ6: =$G6*AO6 -> 0 | AS6: =AR6*$B$123 -> 0 | AT6: =$G6*AR6 -> 0 | AV6: =AU6*$B$124 -> 0 | AW6: =$G6*AU6 -> 0 | AY6: =AX6*$B$125 -> 0 | AZ6: =$G6*AX6 -> 0 | BB6: =BA6*$B$126 -> 0 | BC6: =$G6*BA6 -> 0 | BE6: =BD6*$B$127 -> 0 | BF6: =$G6*BD6 -> 0 | BH6: =BG6*$B$128 -> 0 | BI6: =$G6*BG6 -> 0 | BK6: =BJ6*$B$129 -> 0 | BL6: =$G6*BJ6 -> 0 | BN6: =BM6*$B$130 -> 0 | BO6: =$G6*BM6 -> 0 | BQ6: =BP6*$B$131 -> 0 | BR6: =$G6*BP6 -> 0 | BT6: =BS6*$B$132 -> 0 | BU6: =$G6*BS6 -> 0 | BW6: =BV6*$B$133 -> 0 | BX6: =$G6*BV6 -> 0 | BZ6: =BY6*$B$134 -> 0 | CA6: =$G6*BY6 -> 0 | CC6: =CB6*$B$135 -> 0 | CD6: =$G6*CB6 -> 0 | CF6: =CE6*$B$136 -> 0 | CG6: =$G6*CE6 -> 0 | CI6: =CH6*$B$137 -> 0 | CJ6: =$G6*CH6 -> 0 | CL6: =CK6*$B$138 -> 0 | CM6: =$G6*CK6 -> 0 | CO6: =CN6*$B$139 -> 0 | CP6: =$G6*CN6 -> 0 | CR6: =CQ6*$B$140 -> 0 | CS6: =$G6*CQ6 -> 0 | CU6: =CT6*$B$141 -> 0 | CV6: =$G6*CT6 -> 0 | CX6: =CW6*$B$142 -> 0 | CY6: =$G6*CW6 -> 0 | DA6: =CZ6*$B$143 -> 0 | DB6: =$G6*CZ6 -> 0 | DD6: =DC6*$B$144 -> 0 | DE6: =$G6*DC6 -> 0 | DG6: =DF6*$B$145 -> 0 | DH6: =$G6*DF6 -> 0 | DJ6: =DI6*$B$146 -> 0 | DK6: =$G6*DI6 -> 0 | DM6: =DL6*$B$147 -> 0 | DN6: =$G6*DL6 -> 0 | DP6: =DO6*$B$148 -> 0 | DQ6: =$G6*DO6 -> 0 | DS6: =DR6*$B$149 -> 0 | DT6: =$G6*DR6 -> 0 | DV6: =DU6*$B$150 -> 0 | DW6: =$G6*DU6 -> 0 | DY6: =DX6*$B$151 -> 0 | DZ6: =$G6*DX6 -> 0 | EB6: =EA6*$B$152 -> 0 | EC6: =$G6*EA6 -> 0 | EE6: =ED6*$B$153 -> 0 | EF6: =$G6*ED6 -> 0 | EH6: =EG6*$B$154 -> 0 | EI6: =$G6*EG6 -> 0 | EK6: =EJ6*$B$155 -> 0 | EL6: =$G6*EJ6 -> 0 | EN6: =EM6*$B$156 -> 0 | EO6: =$G6*EM6 -> 0
A7: 2 | B7: Exit Device | C7: Sargent | D7: 56-NB-PE8613 x WEJ x hand | E7: 626 | F7: =SUM(I7,L7,O7,BN7,R7,U7,X7,AA7,BZ7,CC7,CF7,AD7,AG7,AJ7,AM7,AP7,AS7,AV7,AY7,BB7,BE7,BH7,BK7,BQ7,BT7,BW7,CI7,CL7,CO7,CR7,CU7,CX7,DA7,DD7,DG7,DJ7,DM7,DP7,DS7,DV7,DY7,EB7,EE7,EH7,EK7,EN7) -> 2 | H7: 2 | I7: =H7*$B$111 -> 2 | J7: =$G7*H7 -> 0 | L7: =K7*$B$112 -> 0 | M7: =$G7*K7 -> 0 | O7: =N7*$B$113 -> 0 | P7: =$G7*N7 -> 0 | R7: =Q7*$B$114 -> 0 | S7: =$G7*Q7 -> 0 | U7: =T7*$B$115 -> 0 | V7: =$G7*T7 -> 0 | X7: =W7*$B$116 -> 0 | Y7: =$G7*W7 -> 0 | AA7: =Z7*$B$117 -> 0 | AB7: =$G7*Z7 -> 0 | AD7: =AC7*$B$118 -> 0 | AE7: =$G7*AC7 -> 0 | AG7: =AF7*$B$119 -> 0 | AH7: =$G7*AF7 -> 0 | AJ7: =AI7*$B$120 -> 0 | AK7: =$G7*AI7 -> 0 | AM7: =AL7*$B$121 -> 0 | AN7: =$G7*AL7 -> 0 | AP7: =AO7*$B$122 -> 0 | AQ7: =$G7*AO7 -> 0 | AS7: =AR7*$B$123 -> 0 | AT7: =$G7*AR7 -> 0 | AV7: =AU7*$B$124 -> 0 | AW7: =$G7*AU7 -> 0 | AY7: =AX7*$B$125 -> 0 | AZ7: =$G7*AX7 -> 0 | BB7: =BA7*$B$126 -> 0 | BC7: =$G7*BA7 -> 0 | BE7: =BD7*$B$127 -> 0 | BF7: =$G7*BD7 -> 0 | BH7: =BG7*$B$128 -> 0 | BI7: =$G7*BG7 -> 0 | BK7: =BJ7*$B$129 -> 0 | BL7: =$G7*BJ7 -> 0 | BN7: =BM7*$B$130 -> 0 | BO7: =$G7*BM7 -> 0 | BQ7: =BP7*$B$131 -> 0 | BR7: =$G7*BP7 -> 0 | BT7: =BS7*$B$132 -> 0 | BU7: =$G7*BS7 -> 0 | BW7: =BV7*$B$133 -> 0 | BX7: =$G7*BV7 -> 0 | BZ7: =BY7*$B$134 -> 0 | CA7: =$G7*BY7 -> 0 | CC7: =CB7*$B$135 -> 0 | CD7: =$G7*CB7 -> 0 | CF7: =CE7*$B$136 -> 0 | CG7: =$G7*CE7 -> 0 | CI7: =CH7*$B$137 -> 0 | CJ7: =$G7*CH7 -> 0 | CL7: =CK7*$B$138 -> 0 | CM7: =$G7*CK7 -> 0 | CO7: =CN7*$B$139 -> 0 | CP7: =$G7*CN7 -> 0 | CR7: =CQ7*$B$140 -> 0 | CS7: =$G7*CQ7 -> 0 | CU7: =CT7*$B$141 -> 0 | CV7: =$G7*CT7 -> 0 | CX7: =CW7*$B$142 -> 0 | CY7: =$G7*CW7 -> 0 | DA7: =CZ7*$B$143 -> 0 | DB7: =$G7*CZ7 -> 0 | DD7: =DC7*$B$144 -> 0 | DE7: =$G7*DC7 -> 0 | DG7: =DF7*$B$145 -> 0 | DH7: =$G7*DF7 -> 0 | DJ7: =DI7*$B$146 -> 0 | DK7: =$G7*DI7 -> 0 | DM7: =DL7*$B$147 -> 0 | DN7: =$G7*DL7 -> 0 | DP7: =DO7*$B$148 -> 0 | DQ7: =$G7*DO7 -> 0 | DS7: =DR7*$B$149 -> 0 | DT7: =$G7*DR7 -> 0 | DV7: =DU7*$B$150 -> 0 | DW7: =$G7*DU7 -> 0 | DY7: =DX7*$B$151 -> 0 | DZ7: =$G7*DX7 -> 0 | EB7: =EA7*$B$152 -> 0 | EC7: =$G7*EA7 -> 0 | EE7: =ED7*$B$153 -> 0 | EF7: =$G7*ED7 -> 0 | EH7: =EG7*$B$154 -> 0 | EI7: =$G7*EG7 -> 0 | EK7: =EJ7*$B$155 -> 0 | EL7: =$G7*EJ7 -> 0 | EN7: =EM7*$B$156 -> 0 | EO7: =$G7*EM7 -> 0
A8: 3 | B8: Cylinder | C8: Schlage | D8: C' Kwy. Type x Length x Cam to suit | E8: 626 | F8: =SUM(I8,L8,O8,BN8,R8,U8,X8,AA8,BZ8,CC8,CF8,AD8,AG8,AJ8,AM8,AP8,AS8,AV8,AY8,BB8,BE8,BH8,BK8,BQ8,BT8,BW8,CI8,CL8,CO8,CR8,CU8,CX8,DA8,DD8,DG8,DJ8,DM8,DP8,DS8,DV8,DY8,EB8,EE8,EH8,EK8,EN8) -> 30 | H8: 3 | I8: =H8*$B$111 -> 3 | J8: =$G8*H8 -> 0 | L8: =K8*$B$112 -> 0 | M8: =$G8*K8 -> 0 | O8: =N8*$B$113 -> 0 | P8: =$G8*N8 -> 0 | Q8: 3 | R8: =Q8*$B$114 -> 3 | S8: =$G8*Q8 -> 0 | T8: 3 | U8: =T8*$B$115 -> 3 | V8: =$G8*T8 -> 0 | X8: =W8*$B$116 -> 0 | Y8: =$G8*W8 -> 0 | Z8: 1 | AA8: =Z8*$B$117 -> 1 | AB8: =$G8*Z8 -> 0 | AC8: 2 | AD8: =AC8*$B$118 -> 2 | AE8: =$G8*AC8 -> 0 | AG8: =AF8*$B$119 -> 0 | AH8: =$G8*AF8 -> 0 | AI8: 1 | AJ8: =AI8*$B$120 -> 3 | AK8: =$G8*AI8 -> 0 | AL8: 1 | AM8: =AL8*$B$121 -> 2 | AN8: =$G8*AL8 -> 0 | AO8: 1 | AP8: =AO8*$B$122 -> 1 | AQ8: =$G8*AO8 -> 0 | AR8: 1 | AS8: =AR8*$B$123 -> 1 | AT8: =$G8*AR8 -> 0 | AV8: =AU8*$B$124 -> 0 | AW8: =$G8*AU8 -> 0 | AY8: =AX8*$B$125 -> 0 | AZ8: =$G8*AX8 -> 0 | BA8: 1 | BB8: =BA8*$B$126 -> 2 | BC8: =$G8*BA8 -> 0 | BD8: 1 | BE8: =BD8*$B$127 -> 1 | BF8: =$G8*BD8 -> 0 | BG8: 1 | BH8: =BG8*$B$128 -> 1 | BI8: =$G8*BG8 -> 0 | BJ8: 1 | BK8: =BJ8*$B$129 -> 1 | BL8: =$G8*BJ8 -> 0 | BN8: =BM8*$B$130 -> 0 | BO8: =$G8*BM8 -> 0 | BQ8: =BP8*$B$131 -> 0 | BR8: =$G8*BP8 -> 0 | BT8: =BS8*$B$132 -> 0 | BU8: =$G8*BS8 -> 0 | BV8: 1 | BW8: =BV8*$B$133 -> 2 | BX8: =$G8*BV8 -> 0 | BY8: 1 | BZ8: =BY8*$B$134 -> 3 | CA8: =$G8*BY8 -> 0 | CB8: 1 | CC8: =CB8*$B$135 -> 1 | CD8: =$G8*CB8 -> 0 | CF8: =CE8*$B$136 -> 0 | CG8: =$G8*CE8 -> 0 | CI8: =CH8*$B$137 -> 0 | CJ8: =$G8*CH8 -> 0 | CL8: =CK8*$B$138 -> 0 | CM8: =$G8*CK8 -> 0 | CO8: =CN8*$B$139 -> 0 | CP8: =$G8*CN8 -> 0 | CR8: =CQ8*$B$140 -> 0 | CS8: =$G8*CQ8 -> 0 | CU8: =CT8*$B$141 -> 0 | CV8: =$G8*CT8 -> 0 | CX8: =CW8*$B$142 -> 0 | CY8: =$G8*CW8 -> 0 | DA8: =CZ8*$B$143 -> 0 | DB8: =$G8*CZ8 -> 0 | DD8: =DC8*$B$144 -> 0 | DE8: =$G8*DC8 -> 0 | DG8: =DF8*$B$145 -> 0 | DH8: =$G8*DF8 -> 0 | DJ8: =DI8*$B$146 -> 0 | DK8: =$G8*DI8 -> 0 | DM8: =DL8*$B$147 -> 0 | DN8: =$G8*DL8 -> 0 | DP8: =DO8*$B$148 -> 0 | DQ8: =$G8*DO8 -> 0 | DS8: =DR8*$B$149 -> 0 | DT8: =$G8*DR8 -> 0 | DV8: =DU8*$B$150 -> 0 | DW8: =$G8*DU8 -> 0 | DY8: =DX8*$B$151 -> 0 | DZ8: =$G8*DX8 -> 0 | EB8: =EA8*$B$152 -> 0 | EC8: =$G8*EA8 -> 0 | EE8: =ED8*$B$153 -> 0 | EF8: =$G8*ED8 -> 0 | EH8: =EG8*$B$154 -> 0 | EI8: =$G8*EG8 -> 0 | EK8: =EJ8*$B$155 -> 0 | EL8: =$G8*EJ8 -> 0 | EN8: =EM8*$B$156 -> 0 | EO8: =$G8*EM8 -> 0
A9: 4 | B9: Exit Device | C9: Detex | D9: F-81-08DV(S lever)-630-hand-LD-EExER-630-95T- height-EC1-SN1 | F9: =SUM(I9,L9,O9,BN9,R9,U9,X9,AA9,BZ9,CC9,CF9,AD9,AG9,AJ9,AM9,AP9,AS9,AV9,AY9,BB9,BE9,BH9,BK9,BQ9,BT9,BW9,CI9,CL9,CO9,CR9,CU9,CX9,DA9,DD9,DG9,DJ9,DM9,DP9,DS9,DV9,DY9,EB9,EE9,EH9,EK9,EN9) -> 4 | I9: =H9*$B$111 -> 0 | J9: =$G9*H9 -> 0 | L9: =K9*$B$112 -> 0 | M9: =$G9*K9 -> 0 | O9: =N9*$B$113 -> 0 | P9: =$G9*N9 -> 0 | Q9: 2 | R9: =Q9*$B$114 -> 2 | S9: =$G9*Q9 -> 0 | T9: 2 | U9: =T9*$B$115 -> 2 | V9: =$G9*T9 -> 0 | X9: =W9*$B$116 -> 0 | Y9: =$G9*W9 -> 0 | AA9: =Z9*$B$117 -> 0 | AB9: =$G9*Z9 -> 0 | AD9: =AC9*$B$118 -> 0 | AE9: =$G9*AC9 -> 0 | AG9: =AF9*$B$119 -> 0 | AH9: =$G9*AF9 -> 0 | AJ9: =AI9*$B$120 -> 0 | AK9: =$G9*AI9 -> 0 | AM9: =AL9*$B$121 -> 0 | AN9: =$G9*AL9 -> 0 | AP9: =AO9*$B$122 -> 0 | AQ9: =$G9*AO9 -> 0 | AS9: =AR9*$B$123 -> 0 | AT9: =$G9*AR9 -> 0 | AV9: =AU9*$B$124 -> 0 | AW9: =$G9*AU9 -> 0 | AY9: =AX9*$B$125 -> 0 | AZ9: =$G9*AX9 -> 0 | BB9: =BA9*$B$126 -> 0 | BC9: =$G9*BA9 -> 0 | BE9: =BD9*$B$127 -> 0 | BF9: =$G9*BD9 -> 0 | BH9: =BG9*$B$128 -> 0 | BI9: =$G9*BG9 -> 0 | BK9: =BJ9*$B$129 -> 0 | BL9: =$G9*BJ9 -> 0 | BN9: =BM9*$B$130 -> 0 | BO9: =$G9*BM9 -> 0 | BQ9: =BP9*$B$131 -> 0 | BR9: =$G9*BP9 -> 0 | BT9: =BS9*$B$132 -> 0 | BU9: =$G9*BS9 -> 0 | BW9: =BV9*$B$133 -> 0 | BX9: =$G9*BV9 -> 0 | BZ9: =BY9*$B$134 -> 0 | CA9: =$G9*BY9 -> 0 | CC9: =CB9*$B$135 -> 0 | CD9: =$G9*CB9 -> 0 | CF9: =CE9*$B$136 -> 0 | CG9: =$G9*CE9 -> 0 | CI9: =CH9*$B$137 -> 0 | CJ9: =$G9*CH9 -> 0 | CL9: =CK9*$B$138 -> 0 | CM9: =$G9*CK9 -> 0 | CO9: =CN9*$B$139 -> 0 | CP9: =$G9*CN9 -> 0 | CR9: =CQ9*$B$140 -> 0 | CS9: =$G9*CQ9 -> 0 | CU9: =CT9*$B$141 -> 0 | CV9: =$G9*CT9 -> 0 | CX9: =CW9*$B$142 -> 0 | CY9: =$G9*CW9 -> 0 | DA9: =CZ9*$B$143 -> 0 | DB9: =$G9*CZ9 -> 0 | DD9: =DC9*$B$144 -> 0 | DE9: =$G9*DC9 -> 0 | DG9: =DF9*$B$145 -> 0 | DH9: =$G9*DF9 -> 0 | DJ9: =DI9*$B$146 -> 0 | DK9: =$G9*DI9 -> 0 | DM9: =DL9*$B$147 -> 0 | DN9: =$G9*DL9 -> 0 | DP9: =DO9*$B$148 -> 0 | DQ9: =$G9*DO9 -> 0 | DS9: =DR9*$B$149 -> 0 | DT9: =$G9*DR9 -> 0 | DV9: =DU9*$B$150 -> 0 | DW9: =$G9*DU9 -> 0 | DY9: =DX9*$B$151 -> 0 | DZ9: =$G9*DX9 -> 0 | EB9: =EA9*$B$152 -> 0 | EC9: =$G9*EA9 -> 0 | EE9: =ED9*$B$153 -> 0 | EF9: =$G9*ED9 -> 0 | EH9: =EG9*$B$154 -> 0 | EI9: =$G9*EG9 -> 0 | EK9: =EJ9*$B$155 -> 0 | EL9: =$G9*EJ9 -> 0 | EN9: =EM9*$B$156 -> 0 | EO9: =$G9*EM9 -> 0
A10: 5 | B10: Passage Set | C10: Sargent | D10: 55-56-8215 x LNJ x hand | E10: 626 | F10: =SUM(I10,L10,O10,BN10,R10,U10,X10,AA10,BZ10,CC10,CF10,AD10,AG10,AJ10,AM10,AP10,AS10,AV10,AY10,BB10,BE10,BH10,BK10,BQ10,BT10,BW10,CI10,CL10,CO10,CR10,CU10,CX10,DA10,DD10,DG10,DJ10,DM10,DP10,DS10,DV10,DY10,EB10,EE10,EH10,EK10,EN10) -> 4 | I10: =H10*$B$111 -> 0 | J10: =$G10*H10 -> 0 | L10: =K10*$B$112 -> 0 | M10: =$G10*K10 -> 0 | O10: =N10*$B$113 -> 0 | P10: =$G10*N10 -> 0 | R10: =Q10*$B$114 -> 0 | S10: =$G10*Q10 -> 0 | U10: =T10*$B$115 -> 0 | V10: =$G10*T10 -> 0 | W10: 1 | X10: =W10*$B$116 -> 4 | Y10: =$G10*W10 -> 0 | AA10: =Z10*$B$117 -> 0 | AB10: =$G10*Z10 -> 0 | AD10: =AC10*$B$118 -> 0 | AE10: =$G10*AC10 -> 0 | AG10: =AF10*$B$119 -> 0 | AH10: =$G10*AF10 -> 0 | AJ10: =AI10*$B$120 -> 0 | AK10: =$G10*AI10 -> 0 | AM10: =AL10*$B$121 -> 0 | AN10: =$G10*AL10 -> 0 | AP10: =AO10*$B$122 -> 0 | AQ10: =$G10*AO10 -> 0 | AS10: =AR10*$B$123 -> 0 | AT10: =$G10*AR10 -> 0 | AV10: =AU10*$B$124 -> 0 | AW10: =$G10*AU10 -> 0 | AY10: =AX10*$B$125 -> 0 | AZ10: =$G10*AX10 -> 0 | BB10: =BA10*$B$126 -> 0 | BC10: =$G10*BA10 -> 0 | BE10: =BD10*$B$127 -> 0 | BF10: =$G10*BD10 -> 0 | BH10: =BG10*$B$128 -> 0 | BI10: =$G10*BG10 -> 0 | BK10: =BJ10*$B$129 -> 0 | BL10: =$G10*BJ10 -> 0 | BN10: =BM10*$B$130 -> 0 | BO10: =$G10*BM10 -> 0 | BQ10: =BP10*$B$131 -> 0 | BR10: =$G10*BP10 -> 0 | BT10: =BS10*$B$132 -> 0 | BU10: =$G10*BS10 -> 0 | BW10: =BV10*$B$133 -> 0 | BX10: =$G10*BV10 -> 0 | BZ10: =BY10*$B$134 -> 0 | CA10: =$G10*BY10 -> 0 | CC10: =CB10*$B$135 -> 0 | CD10: =$G10*CB10 -> 0 | CF10: =CE10*$B$136 -> 0 | CG10: =$G10*CE10 -> 0 | CI10: =CH10*$B$137 -> 0 | CJ10: =$G10*CH10 -> 0 | CL10: =CK10*$B$138 -> 0 | CM10: =$G10*CK10 -> 0 | CO10: =CN10*$B$139 -> 0 | CP10: =$G10*CN10 -> 0 | CR10: =CQ10*$B$140 -> 0 | CS10: =$G10*CQ10 -> 0 | CU10: =CT10*$B$141 -> 0 | CV10: =$G10*CT10 -> 0 | CX10: =CW10*$B$142 -> 0 | CY10: =$G10*CW10 -> 0 | DA10: =CZ10*$B$143 -> 0 | DB10: =$G10*CZ10 -> 0 | DD10: =DC10*$B$144 -> 0 | DE10: =$G10*DC10 -> 0 | DG10: =DF10*$B$145 -> 0 | DH10: =$G10*DF10 -> 0 | DJ10: =DI10*$B$146 -> 0 | DK10: =$G10*DI10 -> 0 | DM10: =DL10*$B$147 -> 0 | DN10: =$G10*DL10 -> 0 | DP10: =DO10*$B$148 -> 0 | DQ10: =$G10*DO10 -> 0 | DS10: =DR10*$B$149 -> 0 | DT10: =$G10*DR10 -> 0 | DV10: =DU10*$B$150 -> 0 | DW10: =$G10*DU10 -> 0 | DY10: =DX10*$B$151 -> 0 | DZ10: =$G10*DX10 -> 0 | EB10: =EA10*$B$152 -> 0 | EC10: =$G10*EA10 -> 0 | EE10: =ED10*$B$153 -> 0 | EF10: =$G10*ED10 -> 0 | EH10: =EG10*$B$154 -> 0 | EI10: =$G10*EG10 -> 0 | EK10: =EJ10*$B$155 -> 0 | EL10: =$G10*EJ10 -> 0 | EN10: =EM10*$B$156 -> 0 | EO10: =$G10*EM10 -> 0
A11: 6 | B11: Storeroom Lockset | C11: Sargent | D11: 54-55-56-8204 x LNJ x hand | E11: 626 | F11: =SUM(I11,L11,O11,BN11,R11,U11,X11,AA11,BZ11,CC11,CF11,AD11,AG11,AJ11,AM11,AP11,AS11,AV11,AY11,BB11,BE11,BH11,BK11,BQ11,BT11,BW11,CI11,CL11,CO11,CR11,CU11,CX11,DA11,DD11,DG11,DJ11,DM11,DP11,DS11,DV11,DY11,EB11,EE11,EH11,EK11,EN11) -> 2 | I11: =H11*$B$111 -> 0 | J11: =$G11*H11 -> 0 | L11: =K11*$B$112 -> 0 | M11: =$G11*K11 -> 0 | O11: =N11*$B$113 -> 0 | P11: =$G11*N11 -> 0 | R11: =Q11*$B$114 -> 0 | S11: =$G11*Q11 -> 0 | U11: =T11*$B$115 -> 0 | V11: =$G11*T11 -> 0 | X11: =W11*$B$116 -> 0 | Y11: =$G11*W11 -> 0 | Z11: 1 | AA11: =Z11*$B$117 -> 1 | AB11: =$G11*Z11 -> 0 | AC11: 1 | AD11: =AC11*$B$118 -> 1 | AE11: =$G11*AC11 -> 0 | AG11: =AF11*$B$119 -> 0 | AH11: =$G11*AF11 -> 0 | AJ11: =AI11*$B$120 -> 0 | AK11: =$G11*AI11 -> 0 | AM11: =AL11*$B$121 -> 0 | AN11: =$G11*AL11 -> 0 | AP11: =AO11*$B$122 -> 0 | AQ11: =$G11*AO11 -> 0 | AS11: =AR11*$B$123 -> 0 | AT11: =$G11*AR11 -> 0 | AV11: =AU11*$B$124 -> 0 | AW11: =$G11*AU11 -> 0 | AY11: =AX11*$B$125 -> 0 | AZ11: =$G11*AX11 -> 0 | BB11: =BA11*$B$126 -> 0 | BC11: =$G11*BA11 -> 0 | BE11: =BD11*$B$127 -> 0 | BF11: =$G11*BD11 -> 0 | BH11: =BG11*$B$128 -> 0 | BI11: =$G11*BG11 -> 0 | BK11: =BJ11*$B$129 -> 0 | BL11: =$G11*BJ11 -> 0 | BN11: =BM11*$B$130 -> 0 | BO11: =$G11*BM11 -> 0 | BQ11: =BP11*$B$131 -> 0 | BR11: =$G11*BP11 -> 0 | BT11: =BS11*$B$132 -> 0 | BU11: =$G11*BS11 -> 0 | BW11: =BV11*$B$133 -> 0 | BX11: =$G11*BV11 -> 0 | BZ11: =BY11*$B$134 -> 0 | CA11: =$G11*BY11 -> 0 | CC11: =CB11*$B$135 -> 0 | CD11: =$G11*CB11 -> 0 | CF11: =CE11*$B$136 -> 0 | CG11: =$G11*CE11 -> 0 | CI11: =CH11*$B$137 -> 0 | CJ11: =$G11*CH11 -> 0 | CL11: =CK11*$B$138 -> 0 | CM11: =$G11*CK11 -> 0 | CO11: =CN11*$B$139 -> 0 | CP11: =$G11*CN11 -> 0 | CR11: =CQ11*$B$140 -> 0 | CS11: =$G11*CQ11 -> 0 | CU11: =CT11*$B$141 -> 0 | CV11: =$G11*CT11 -> 0 | CX11: =CW11*$B$142 -> 0 | CY11: =$G11*CW11 -> 0 | DA11: =CZ11*$B$143 -> 0 | DB11: =$G11*CZ11 -> 0 | DD11: =DC11*$B$144 -> 0 | DE11: =$G11*DC11 -> 0 | DG11: =DF11*$B$145 -> 0 | DH11: =$G11*DF11 -> 0 | DJ11: =DI11*$B$146 -> 0 | DK11: =$G11*DI11 -> 0 | DM11: =DL11*$B$147 -> 0 | DN11: =$G11*DL11 -> 0 | DP11: =DO11*$B$148 -> 0 | DQ11: =$G11*DO11 -> 0 | DS11: =DR11*$B$149 -> 0 | DT11: =$G11*DR11 -> 0 | DV11: =DU11*$B$150 -> 0 | DW11: =$G11*DU11 -> 0 | DY11: =DX11*$B$151 -> 0 | DZ11: =$G11*DX11 -> 0 | EB11: =EA11*$B$152 -> 0 | EC11: =$G11*EA11 -> 0 | EE11: =ED11*$B$153 -> 0 | EF11: =$G11*ED11 -> 0 | EH11: =EG11*$B$154 -> 0 | EI11: =$G11*EG11 -> 0 | EK11: =EJ11*$B$155 -> 0 | EL11: =$G11*EJ11 -> 0 | EN11: =EM11*$B$156 -> 0 | EO11: =$G11*EM11 -> 0
A12: 7 | B12: Continuous Hinge | C12: Pemko | D12: DSHPO1C-84-Torx | F12: =SUM(I12,L12,O12,BN12,R12,U12,X12,AA12,BZ12,CC12,CF12,AD12,AG12,AJ12,AM12,AP12,AS12,AV12,AY12,BB12,BE12,BH12,BK12,BQ12,BT12,BW12,CI12,CL12,CO12,CR12,CU12,CX12,DA12,DD12,DG12,DJ12,DM12,DP12,DS12,DV12,DY12,EB12,EE12,EH12,EK12,EN12) -> 8 | I12: =H12*$B$111 -> 0 | J12: =$G12*H12 -> 0 | L12: =K12*$B$112 -> 0 | M12: =$G12*K12 -> 0 | O12: =N12*$B$113 -> 0 | P12: =$G12*N12 -> 0 | R12: =Q12*$B$114 -> 0 | S12: =$G12*Q12 -> 0 | U12: =T12*$B$115 -> 0 | V12: =$G12*T12 -> 0 | X12: =W12*$B$116 -> 0 | Y12: =$G12*W12 -> 0 | AA12: =Z12*$B$117 -> 0 | AB12: =$G12*Z12 -> 0 | AD12: =AC12*$B$118 -> 0 | AE12: =$G12*AC12 -> 0 | AG12: =AF12*$B$119 -> 0 | AH12: =$G12*AF12 -> 0 | AJ12: =AI12*$B$120 -> 0 | AK12: =$G12*AI12 -> 0 | AM12: =AL12*$B$121 -> 0 | AN12: =$G12*AL12 -> 0 | AP12: =AO12*$B$122 -> 0 | AQ12: =$G12*AO12 -> 0 | AS12: =AR12*$B$123 -> 0 | AT12: =$G12*AR12 -> 0 | AV12: =AU12*$B$124 -> 0 | AW12: =$G12*AU12 -> 0 | AY12: =AX12*$B$125 -> 0 | AZ12: =$G12*AX12 -> 0 | BA12: 1 | BB12: =BA12*$B$126 -> 2 | BC12: =$G12*BA12 -> 0 | BE12: =BD12*$B$127 -> 0 | BF12: =$G12*BD12 -> 0 | BH12: =BG12*$B$128 -> 0 | BI12: =$G12*BG12 -> 0 | BK12: =BJ12*$B$129 -> 0 | BL12: =$G12*BJ12 -> 0 | BN12: =BM12*$B$130 -> 0 | BO12: =$G12*BM12 -> 0 | BQ12: =BP12*$B$131 -> 0 | BR12: =$G12*BP12 -> 0 | BS12: 1 | BT12: =BS12*$B$132 -> 1 | BU12: =$G12*BS12 -> 0 | BV12: 1 | BW12: =BV12*$B$133 -> 2 | BX12: =$G12*BV12 -> 0 | BY12: 1 | BZ12: =BY12*$B$134 -> 3 | CA12: =$G12*BY12 -> 0 | CC12: =CB12*$B$135 -> 0 | CD12: =$G12*CB12 -> 0 | CF12: =CE12*$B$136 -> 0 | CG12: =$G12*CE12 -> 0 | CI12: =CH12*$B$137 -> 0 | CJ12: =$G12*CH12 -> 0 | CL12: =CK12*$B$138 -> 0 | CM12: =$G12*CK12 -> 0 | CO12: =CN12*$B$139 -> 0 | CP12: =$G12*CN12 -> 0 | CR12: =CQ12*$B$140 -> 0 | CS12: =$G12*CQ12 -> 0 | CU12: =CT12*$B$141 -> 0 | CV12: =$G12*CT12 -> 0 | CX12: =CW12*$B$142 -> 0 | CY12: =$G12*CW12 -> 0 | DA12: =CZ12*$B$143 -> 0 | DB12: =$G12*CZ12 -> 0 | DD12: =DC12*$B$144 -> 0 | DE12: =$G12*DC12 -> 0 | DG12: =DF12*$B$145 -> 0 | DH12: =$G12*DF12 -> 0 | DJ12: =DI12*$B$146 -> 0 | DK12: =$G12*DI12 -> 0 | DM12: =DL12*$B$147 -> 0 | DN12: =$G12*DL12 -> 0 | DP12: =DO12*$B$148 -> 0 | DQ12: =$G12*DO12 -> 0 | DS12: =DR12*$B$149 -> 0 | DT12: =$G12*DR12 -> 0 | DV12: =DU12*$B$150 -> 0 | DW12: =$G12*DU12 -> 0 | DY12: =DX12*$B$151 -> 0 | DZ12: =$G12*DX12 -> 0 | EB12: =EA12*$B$152 -> 0 | EC12: =$G12*EA12 -> 0 | EE12: =ED12*$B$153 -> 0 | EF12: =$G12*ED12 -> 0 | EH12: =EG12*$B$154 -> 0 | EI12: =$G12*EG12 -> 0 | EK12: =EJ12*$B$155 -> 0 | EL12: =$G12*EJ12 -> 0 | EN12: =EM12*$B$156 -> 0 | EO12: =$G12*EM12 -> 0
A13: 8 | B13: Continuous Hinge | C13: McKinney | D13: (83") FM-HD1 x length | F13: =SUM(I13,L13,O13,BN13,R13,U13,X13,AA13,BZ13,CC13,CF13,AD13,AG13,AJ13,AM13,AP13,AS13,AV13,AY13,BB13,BE13,BH13,BK13,BQ13,BT13,BW13,CI13,CL13,CO13,CR13,CU13,CX13,DA13,DD13,DG13,DJ13,DM13,DP13,DS13,DV13,DY13,EB13,EE13,EH13,EK13,EN13) -> 5 | I13: =H13*$B$111 -> 0 | J13: =$G13*H13 -> 0 | L13: =K13*$B$112 -> 0 | M13: =$G13*K13 -> 0 | O13: =N13*$B$113 -> 0 | P13: =$G13*N13 -> 0 | R13: =Q13*$B$114 -> 0 | S13: =$G13*Q13 -> 0 | U13: =T13*$B$115 -> 0 | V13: =$G13*T13 -> 0 | X13: =W13*$B$116 -> 0 | Y13: =$G13*W13 -> 0 | AA13: =Z13*$B$117 -> 0 | AB13: =$G13*Z13 -> 0 | AC13: 1 | AD13: =AC13*$B$118 -> 1 | AE13: =$G13*AC13 -> 0 | AG13: =AF13*$B$119 -> 0 | AH13: =$G13*AF13 -> 0 | AJ13: =AI13*$B$120 -> 0 | AK13: =$G13*AI13 -> 0 | AM13: =AL13*$B$121 -> 0 | AN13: =$G13*AL13 -> 0 | AP13: =AO13*$B$122 -> 0 | AQ13: =$G13*AO13 -> 0 | AS13: =AR13*$B$123 -> 0 | AT13: =$G13*AR13 -> 0 | AV13: =AU13*$B$124 -> 0 | AW13: =$G13*AU13 -> 0 | AX13: 2 | AY13: =AX13*$B$125 -> 2 | AZ13: =$G13*AX13 -> 0 | BB13: =BA13*$B$126 -> 0 | BC13: =$G13*BA13 -> 0 | BE13: =BD13*$B$127 -> 0 | BF13: =$G13*BD13 -> 0 | BH13: =BG13*$B$128 -> 0 | BI13: =$G13*BG13 -> 0 | BJ13: 2 | BK13: =BJ13*$B$129 -> 2 | BL13: =$G13*BJ13 -> 0 | BN13: =BM13*$B$130 -> 0 | BO13: =$G13*BM13 -> 0 | BQ13: =BP13*$B$131 -> 0 | BR13: =$G13*BP13 -> 0 | BT13: =BS13*$B$132 -> 0 | BU13: =$G13*BS13 -> 0 | BW13: =BV13*$B$133 -> 0 | BX13: =$G13*BV13 -> 0 | BZ13: =BY13*$B$134 -> 0 | CA13: =$G13*BY13 -> 0 | CC13: =CB13*$B$135 -> 0 | CD13: =$G13*CB13 -> 0 | CF13: =CE13*$B$136 -> 0 | CG13: =$G13*CE13 -> 0 | CI13: =CH13*$B$137 -> 0 | CJ13: =$G13*CH13 -> 0 | CL13: =CK13*$B$138 -> 0 | CM13: =$G13*CK13 -> 0 | CO13: =CN13*$B$139 -> 0 | CP13: =$G13*CN13 -> 0 | CR13: =CQ13*$B$140 -> 0 | CS13: =$G13*CQ13 -> 0 | CU13: =CT13*$B$141 -> 0 | CV13: =$G13*CT13 -> 0 | CX13: =CW13*$B$142 -> 0 | CY13: =$G13*CW13 -> 0 | DA13: =CZ13*$B$143 -> 0 | DB13: =$G13*CZ13 -> 0 | DD13: =DC13*$B$144 -> 0 | DE13: =$G13*DC13 -> 0 | DG13: =DF13*$B$145 -> 0 | DH13: =$G13*DF13 -> 0 | DJ13: =DI13*$B$146 -> 0 | DK13: =$G13*DI13 -> 0 | DM13: =DL13*$B$147 -> 0 | DN13: =$G13*DL13 -> 0 | DP13: =DO13*$B$148 -> 0 | DQ13: =$G13*DO13 -> 0 | DS13: =DR13*$B$149 -> 0 | DT13: =$G13*DR13 -> 0 | DV13: =DU13*$B$150 -> 0 | DW13: =$G13*DU13 -> 0 | DY13: =DX13*$B$151 -> 0 | DZ13: =$G13*DX13 -> 0 | EB13: =EA13*$B$152 -> 0 | EC13: =$G13*EA13 -> 0 | EE13: =ED13*$B$153 -> 0 | EF13: =$G13*ED13 -> 0 | EH13: =EG13*$B$154 -> 0 | EI13: =$G13*EG13 -> 0 | EK13: =EJ13*$B$155 -> 0 | EL13: =$G13*EJ13 -> 0 | EN13: =EM13*$B$156 -> 0 | EO13: =$G13*EM13 -> 0
A14: 9 | B14: Continuous Hinge | C14: McKinney | D14: (83") FM-HD1-SER8 x length | E14: CA | F14: =SUM(I14,L14,O14,BN14,R14,U14,X14,AA14,BZ14,CC14,CF14,AD14,AG14,AJ14,AM14,AP14,AS14,AV14,AY14,BB14,BE14,BH14,BK14,BQ14,BT14,BW14,CI14,CL14,CO14,CR14,CU14,CX14,DA14,DD14,DG14,DJ14,DM14,DP14,DS14,DV14,DY14,EB14,EE14,EH14,EK14,EN14) -> 7 | I14: =H14*$B$111 -> 0 | J14: =$G14*H14 -> 0 | L14: =K14*$B$112 -> 0 | M14: =$G14*K14 -> 0 | O14: =N14*$B$113 -> 0 | P14: =$G14*N14 -> 0 | R14: =Q14*$B$114 -> 0 | S14: =$G14*Q14 -> 0 | U14: =T14*$B$115 -> 0 | V14: =$G14*T14 -> 0 | X14: =W14*$B$116 -> 0 | Y14: =$G14*W14 -> 0 | AA14: =Z14*$B$117 -> 0 | AB14: =$G14*Z14 -> 0 | AD14: =AC14*$B$118 -> 0 | AE14: =$G14*AC14 -> 0 | AG14: =AF14*$B$119 -> 0 | AH14: =$G14*AF14 -> 0 | AI14: 1 | AJ14: =AI14*$B$120 -> 3 | AK14: =$G14*AI14 -> 0 | AL14: 1 | AM14: =AL14*$B$121 -> 2 | AN14: =$G14*AL14 -> 0 | AO14: 1 | AP14: =AO14*$B$122 -> 1 | AQ14: =$G14*AO14 -> 0 | AR14: 1 | AS14: =AR14*$B$123 -> 1 | AT14: =$G14*AR14 -> 0 | AV14: =AU14*$B$124 -> 0 | AW14: =$G14*AU14 -> 0 | AY14: =AX14*$B$125 -> 0 | AZ14: =$G14*AX14 -> 0 | BB14: =BA14*$B$126 -> 0 | BC14: =$G14*BA14 -> 0 | BE14: =BD14*$B$127 -> 0 | BF14: =$G14*BD14 -> 0 | BH14: =BG14*$B$128 -> 0 | BI14: =$G14*BG14 -> 0 | BK14: =BJ14*$B$129 -> 0 | BL14: =$G14*BJ14 -> 0 | BN14: =BM14*$B$130 -> 0 | BO14: =$G14*BM14 -> 0 | BQ14: =BP14*$B$131 -> 0 | BR14: =$G14*BP14 -> 0 | BT14: =BS14*$B$132 -> 0 | BU14: =$G14*BS14 -> 0 | BW14: =BV14*$B$133 -> 0 | BX14: =$G14*BV14 -> 0 | BZ14: =BY14*$B$134 -> 0 | CA14: =$G14*BY14 -> 0 | CC14: =CB14*$B$135 -> 0 | CD14: =$G14*CB14 -> 0 | CF14: =CE14*$B$136 -> 0 | CG14: =$G14*CE14 -> 0 | CI14: =CH14*$B$137 -> 0 | CJ14: =$G14*CH14 -> 0 | CL14: =CK14*$B$138 -> 0 | CM14: =$G14*CK14 -> 0 | CO14: =CN14*$B$139 -> 0 | CP14: =$G14*CN14 -> 0 | CR14: =CQ14*$B$140 -> 0 | CS14: =$G14*CQ14 -> 0 | CU14: =CT14*$B$141 -> 0 | CV14: =$G14*CT14 -> 0 | CX14: =CW14*$B$142 -> 0 | CY14: =$G14*CW14 -> 0 | DA14: =CZ14*$B$143 -> 0 | DB14: =$G14*CZ14 -> 0 | DD14: =DC14*$B$144 -> 0 | DE14: =$G14*DC14 -> 0 | DG14: =DF14*$B$145 -> 0 | DH14: =$G14*DF14 -> 0 | DJ14: =DI14*$B$146 -> 0 | DK14: =$G14*DI14 -> 0 | DM14: =DL14*$B$147 -> 0 | DN14: =$G14*DL14 -> 0 | DP14: =DO14*$B$148 -> 0 | DQ14: =$G14*DO14 -> 0 | DS14: =DR14*$B$149 -> 0 | DT14: =$G14*DR14 -> 0 | DV14: =DU14*$B$150 -> 0 | DW14: =$G14*DU14 -> 0 | DY14: =DX14*$B$151 -> 0 | DZ14: =$G14*DX14 -> 0 | EB14: =EA14*$B$152 -> 0 | EC14: =$G14*EA14 -> 0 | EE14: =ED14*$B$153 -> 0 | EF14: =$G14*ED14 -> 0 | EH14: =EG14*$B$154 -> 0 | EI14: =$G14*EG14 -> 0 | EK14: =EJ14*$B$155 -> 0 | EL14: =$G14*EJ14 -> 0 | EN14: =EM14*$B$156 -> 0 | EO14: =$G14*EM14 -> 0
A15: 10 | B15: Lockset | C15: Sargent | D15: 10XG04 x LL | E15: 626 | F15: =SUM(I15,L15,O15,BN15,R15,U15,X15,AA15,BZ15,CC15,CF15,AD15,AG15,AJ15,AM15,AP15,AS15,AV15,AY15,BB15,BE15,BH15,BK15,BQ15,BT15,BW15,CI15,CL15,CO15,CR15,CU15,CX15,DA15,DD15,DG15,DJ15,DM15,DP15,DS15,DV15,DY15,EB15,EE15,EH15,EK15,EN15) -> 1 | I15: =H15*$B$111 -> 0 | J15: =$G15*H15 -> 0 | L15: =K15*$B$112 -> 0 | M15: =$G15*K15 -> 0 | O15: =N15*$B$113 -> 0 | P15: =$G15*N15 -> 0 | R15: =Q15*$B$114 -> 0 | S15: =$G15*Q15 -> 0 | U15: =T15*$B$115 -> 0 | V15: =$G15*T15 -> 0 | X15: =W15*$B$116 -> 0 | Y15: =$G15*W15 -> 0 | AA15: =Z15*$B$117 -> 0 | AB15: =$G15*Z15 -> 0 | AD15: =AC15*$B$118 -> 0 | AE15: =$G15*AC15 -> 0 | AG15: =AF15*$B$119 -> 0 | AH15: =$G15*AF15 -> 0 | AJ15: =AI15*$B$120 -> 0 | AK15: =$G15*AI15 -> 0 | AM15: =AL15*$B$121 -> 0 | AN15: =$G15*AL15 -> 0 | AP15: =AO15*$B$122 -> 0 | AQ15: =$G15*AO15 -> 0 | AS15: =AR15*$B$123 -> 0 | AT15: =$G15*AR15 -> 0 | AV15: =AU15*$B$124 -> 0 | AW15: =$G15*AU15 -> 0 | AY15: =AX15*$B$125 -> 0 | AZ15: =$G15*AX15 -> 0 | BB15: =BA15*$B$126 -> 0 | BC15: =$G15*BA15 -> 0 | BE15: =BD15*$B$127 -> 0 | BF15: =$G15*BD15 -> 0 | BH15: =BG15*$B$128 -> 0 | BI15: =$G15*BG15 -> 0 | BK15: =BJ15*$B$129 -> 0 | BL15: =$G15*BJ15 -> 0 | BN15: =BM15*$B$130 -> 0 | BO15: =$G15*BM15 -> 0 | BQ15: =BP15*$B$131 -> 0 | BR15: =$G15*BP15 -> 0 | BT15: =BS15*$B$132 -> 0 | BU15: =$G15*BS15 -> 0 | BW15: =BV15*$B$133 -> 0 | BX15: =$G15*BV15 -> 0 | BZ15: =BY15*$B$134 -> 0 | CA15: =$G15*BY15 -> 0 | CB15: 1 | CC15: =CB15*$B$135 -> 1 | CD15: =$G15*CB15 -> 0 | CF15: =CE15*$B$136 -> 0 | CG15: =$G15*CE15 -> 0 | CI15: =CH15*$B$137 -> 0 | CJ15: =$G15*CH15 -> 0 | CL15: =CK15*$B$138 -> 0 | CM15: =$G15*CK15 -> 0 | CO15: =CN15*$B$139 -> 0 | CP15: =$G15*CN15 -> 0 | CR15: =CQ15*$B$140 -> 0 | CS15: =$G15*CQ15 -> 0 | CU15: =CT15*$B$141 -> 0 | CV15: =$G15*CT15 -> 0 | CX15: =CW15*$B$142 -> 0 | CY15: =$G15*CW15 -> 0 | DA15: =CZ15*$B$143 -> 0 | DB15: =$G15*CZ15 -> 0 | DD15: =DC15*$B$144 -> 0 | DE15: =$G15*DC15 -> 0 | DG15: =DF15*$B$145 -> 0 | DH15: =$G15*DF15 -> 0 | DJ15: =DI15*$B$146 -> 0 | DK15: =$G15*DI15 -> 0 | DM15: =DL15*$B$147 -> 0 | DN15: =$G15*DL15 -> 0 | DP15: =DO15*$B$148 -> 0 | DQ15: =$G15*DO15 -> 0 | DS15: =DR15*$B$149 -> 0 | DT15: =$G15*DR15 -> 0 | DV15: =DU15*$B$150 -> 0 | DW15: =$G15*DU15 -> 0 | DY15: =DX15*$B$151 -> 0 | DZ15: =$G15*DX15 -> 0 | EB15: =EA15*$B$152 -> 0 | EC15: =$G15*EA15 -> 0 | EE15: =ED15*$B$153 -> 0 | EF15: =$G15*ED15 -> 0 | EH15: =EG15*$B$154 -> 0 | EI15: =$G15*EG15 -> 0 | EK15: =EJ15*$B$155 -> 0 | EL15: =$G15*EJ15 -> 0 | EN15: =EM15*$B$156 -> 0 | EO15: =$G15*EM15 -> 0
A16: 11 | B16: T/F Hinge | C16: McKinney | D16: T4A4386-QC12 | F16: =SUM(I16,L16,O16,BN16,R16,U16,X16,AA16,BZ16,CC16,CF16,AD16,AG16,AJ16,AM16,AP16,AS16,AV16,AY16,BB16,BE16,BH16,BK16,BQ16,BT16,BW16,CI16,CL16,CO16,CR16,CU16,CX16,DA16,DD16,DG16,DJ16,DM16,DP16,DS16,DV16,DY16,EB16,EE16,EH16,EK16,EN16) -> 1 | I16: =H16*$B$111 -> 0 | J16: =$G16*H16 -> 0 | L16: =K16*$B$112 -> 0 | M16: =$G16*K16 -> 0 | O16: =N16*$B$113 -> 0 | P16: =$G16*N16 -> 0 | R16: =Q16*$B$114 -> 0 | S16: =$G16*Q16 -> 0 | U16: =T16*$B$115 -> 0 | V16: =$G16*T16 -> 0 | X16: =W16*$B$116 -> 0 | Y16: =$G16*W16 -> 0 | Z16: 1 | AA16: =Z16*$B$117 -> 1 | AB16: =$G16*Z16 -> 0 | AD16: =AC16*$B$118 -> 0 | AE16: =$G16*AC16 -> 0 | AG16: =AF16*$B$119 -> 0 | AH16: =$G16*AF16 -> 0 | AJ16: =AI16*$B$120 -> 0 | AK16: =$G16*AI16 -> 0 | AM16: =AL16*$B$121 -> 0 | AN16: =$G16*AL16 -> 0 | AP16: =AO16*$B$122 -> 0 | AQ16: =$G16*AO16 -> 0 | AS16: =AR16*$B$123 -> 0 | AT16: =$G16*AR16 -> 0 | AV16: =AU16*$B$124 -> 0 | AW16: =$G16*AU16 -> 0 | AY16: =AX16*$B$125 -> 0 | AZ16: =$G16*AX16 -> 0 | BB16: =BA16*$B$126 -> 0 | BC16: =$G16*BA16 -> 0 | BE16: =BD16*$B$127 -> 0 | BF16: =$G16*BD16 -> 0 | BH16: =BG16*$B$128 -> 0 | BI16: =$G16*BG16 -> 0 | BK16: =BJ16*$B$129 -> 0 | BL16: =$G16*BJ16 -> 0 | BN16: =BM16*$B$130 -> 0 | BO16: =$G16*BM16 -> 0 | BQ16: =BP16*$B$131 -> 0 | BR16: =$G16*BP16 -> 0 | BT16: =BS16*$B$132 -> 0 | BU16: =$G16*BS16 -> 0 | BW16: =BV16*$B$133 -> 0 | BX16: =$G16*BV16 -> 0 | BZ16: =BY16*$B$134 -> 0 | CA16: =$G16*BY16 -> 0 | CC16: =CB16*$B$135 -> 0 | CD16: =$G16*CB16 -> 0 | CF16: =CE16*$B$136 -> 0 | CG16: =$G16*CE16 -> 0 | CI16: =CH16*$B$137 -> 0 | CJ16: =$G16*CH16 -> 0 | CL16: =CK16*$B$138 -> 0 | CM16: =$G16*CK16 -> 0 | CO16: =CN16*$B$139 -> 0 | CP16: =$G16*CN16 -> 0 | CR16: =CQ16*$B$140 -> 0 | CS16: =$G16*CQ16 -> 0 | CU16: =CT16*$B$141 -> 0 | CV16: =$G16*CT16 -> 0 | CX16: =CW16*$B$142 -> 0 | CY16: =$G16*CW16 -> 0 | DA16: =CZ16*$B$143 -> 0 | DB16: =$G16*CZ16 -> 0 | DD16: =DC16*$B$144 -> 0 | DE16: =$G16*DC16 -> 0 | DG16: =DF16*$B$145 -> 0 | DH16: =$G16*DF16 -> 0 | DJ16: =DI16*$B$146 -> 0 | DK16: =$G16*DI16 -> 0 | DM16: =DL16*$B$147 -> 0 | DN16: =$G16*DL16 -> 0 | DP16: =DO16*$B$148 -> 0 | DQ16: =$G16*DO16 -> 0 | DS16: =DR16*$B$149 -> 0 | DT16: =$G16*DR16 -> 0 | DV16: =DU16*$B$150 -> 0 | DW16: =$G16*DU16 -> 0 | DY16: =DX16*$B$151 -> 0 | DZ16: =$G16*DX16 -> 0 | EB16: =EA16*$B$152 -> 0 | EC16: =$G16*EA16 -> 0 | EE16: =ED16*$B$153 -> 0 | EF16: =$G16*ED16 -> 0 | EH16: =EG16*$B$154 -> 0 | EI16: =$G16*EG16 -> 0 | EK16: =EJ16*$B$155 -> 0 | EL16: =$G16*EJ16 -> 0 | EN16: =EM16*$B$156 -> 0 | EO16: =$G16*EM16 -> 0
A17: 12 | B17: Lock Set | C17: Sargent | D17: RX-82271-LC x LNJ x hand | E17: 626 | F17: =SUM(I17,L17,O17,BN17,R17,U17,X17,AA17,BZ17,CC17,CF17,AD17,AG17,AJ17,AM17,AP17,AS17,AV17,AY17,BB17,BE17,BH17,BK17,BQ17,BT17,BW17,CI17,CL17,CO17,CR17,CU17,CX17,DA17,DD17,DG17,DJ17,DM17,DP17,DS17,DV17,DY17,EB17,EE17,EH17,EK17,EN17) -> 6 | I17: =H17*$B$111 -> 0 | J17: =$G17*H17 -> 0 | L17: =K17*$B$112 -> 0 | M17: =$G17*K17 -> 0 | O17: =N17*$B$113 -> 0 | P17: =$G17*N17 -> 0 | R17: =Q17*$B$114 -> 0 | S17: =$G17*Q17 -> 0 | U17: =T17*$B$115 -> 0 | V17: =$G17*T17 -> 0 | X17: =W17*$B$116 -> 0 | Y17: =$G17*W17 -> 0 | AA17: =Z17*$B$117 -> 0 | AB17: =$G17*Z17 -> 0 | AD17: =AC17*$B$118 -> 0 | AE17: =$G17*AC17 -> 0 | AG17: =AF17*$B$119 -> 0 | AH17: =$G17*AF17 -> 0 | AI17: 1 | AJ17: =AI17*$B$120 -> 3 | AK17: =$G17*AI17 -> 0 | AL17: 1 | AM17: =AL17*$B$121 -> 2 | AN17: =$G17*AL17 -> 0 | AP17: =AO17*$B$122 -> 0 | AQ17: =$G17*AO17 -> 0 | AR17: 1 | AS17: =AR17*$B$123 -> 1 | AT17: =$G17*AR17 -> 0 | AV17: =AU17*$B$124 -> 0 | AW17: =$G17*AU17 -> 0 | AY17: =AX17*$B$125 -> 0 | AZ17: =$G17*AX17 -> 0 | BB17: =BA17*$B$126 -> 0 | BC17: =$G17*BA17 -> 0 | BE17: =BD17*$B$127 -> 0 | BF17: =$G17*BD17 -> 0 | BH17: =BG17*$B$128 -> 0 | BI17: =$G17*BG17 -> 0 | BK17: =BJ17*$B$129 -> 0 | BL17: =$G17*BJ17 -> 0 | BN17: =BM17*$B$130 -> 0 | BO17: =$G17*BM17 -> 0 | BQ17: =BP17*$B$131 -> 0 | BR17: =$G17*BP17 -> 0 | BT17: =BS17*$B$132 -> 0 | BU17: =$G17*BS17 -> 0 | BW17: =BV17*$B$133 -> 0 | BX17: =$G17*BV17 -> 0 | BZ17: =BY17*$B$134 -> 0 | CA17: =$G17*BY17 -> 0 | CC17: =CB17*$B$135 -> 0 | CD17: =$G17*CB17 -> 0 | CF17: =CE17*$B$136 -> 0 | CG17: =$G17*CE17 -> 0 | CI17: =CH17*$B$137 -> 0 | CJ17: =$G17*CH17 -> 0 | CL17: =CK17*$B$138 -> 0 | CM17: =$G17*CK17 -> 0 | CO17: =CN17*$B$139 -> 0 | CP17: =$G17*CN17 -> 0 | CR17: =CQ17*$B$140 -> 0 | CS17: =$G17*CQ17 -> 0 | CU17: =CT17*$B$141 -> 0 | CV17: =$G17*CT17 -> 0 | CX17: =CW17*$B$142 -> 0 | CY17: =$G17*CW17 -> 0 | DA17: =CZ17*$B$143 -> 0 | DB17: =$G17*CZ17 -> 0 | DD17: =DC17*$B$144 -> 0 | DE17: =$G17*DC17 -> 0 | DG17: =DF17*$B$145 -> 0 | DH17: =$G17*DF17 -> 0 | DJ17: =DI17*$B$146 -> 0 | DK17: =$G17*DI17 -> 0 | DM17: =DL17*$B$147 -> 0 | DN17: =$G17*DL17 -> 0 | DP17: =DO17*$B$148 -> 0 | DQ17: =$G17*DO17 -> 0 | DS17: =DR17*$B$149 -> 0 | DT17: =$G17*DR17 -> 0 | DV17: =DU17*$B$150 -> 0 | DW17: =$G17*DU17 -> 0 | DY17: =DX17*$B$151 -> 0 | DZ17: =$G17*DX17 -> 0 | EB17: =EA17*$B$152 -> 0 | EC17: =$G17*EA17 -> 0 | EE17: =ED17*$B$153 -> 0 | EF17: =$G17*ED17 -> 0 | EH17: =EG17*$B$154 -> 0 | EI17: =$G17*EG17 -> 0 | EK17: =EJ17*$B$155 -> 0 | EL17: =$G17*EJ17 -> 0 | EN17: =EM17*$B$156 -> 0 | EO17: =$G17*EM17 -> 0
A18: 13 | B18: Storeroom Lockset | C18: Sargent | D18: 56-8204 x LNJ x hand | E18: 626 | F18: =SUM(I18,L18,O18,BN18,R18,U18,X18,AA18,BZ18,CC18,CF18,AD18,AG18,AJ18,AM18,AP18,AS18,AV18,AY18,BB18,BE18,BH18,BK18,BQ18,BT18,BW18,CI18,CL18,CO18,CR18,CU18,CX18,DA18,DD18,DG18,DJ18,DM18,DP18,DS18,DV18,DY18,EB18,EE18,EH18,EK18,EN18) -> 1 | I18: =H18*$B$111 -> 0 | J18: =$G18*H18 -> 0 | L18: =K18*$B$112 -> 0 | M18: =$G18*K18 -> 0 | O18: =N18*$B$113 -> 0 | P18: =$G18*N18 -> 0 | R18: =Q18*$B$114 -> 0 | S18: =$G18*Q18 -> 0 | U18: =T18*$B$115 -> 0 | V18: =$G18*T18 -> 0 | X18: =W18*$B$116 -> 0 | Y18: =$G18*W18 -> 0 | AA18: =Z18*$B$117 -> 0 | AB18: =$G18*Z18 -> 0 | AD18: =AC18*$B$118 -> 0 | AE18: =$G18*AC18 -> 0 | AG18: =AF18*$B$119 -> 0 | AH18: =$G18*AF18 -> 0 | AJ18: =AI18*$B$120 -> 0 | AK18: =$G18*AI18 -> 0 | AM18: =AL18*$B$121 -> 0 | AN18: =$G18*AL18 -> 0 | AO18: 1 | AP18: =AO18*$B$122 -> 1 | AQ18: =$G18*AO18 -> 0 | AS18: =AR18*$B$123 -> 0 | AT18: =$G18*AR18 -> 0 | AV18: =AU18*$B$124 -> 0 | AW18: =$G18*AU18 -> 0 | AY18: =AX18*$B$125 -> 0 | AZ18: =$G18*AX18 -> 0 | BB18: =BA18*$B$126 -> 0 | BC18: =$G18*BA18 -> 0 | BE18: =BD18*$B$127 -> 0 | BF18: =$G18*BD18 -> 0 | BH18: =BG18*$B$128 -> 0 | BI18: =$G18*BG18 -> 0 | BK18: =BJ18*$B$129 -> 0 | BL18: =$G18*BJ18 -> 0 | BN18: =BM18*$B$130 -> 0 | BO18: =$G18*BM18 -> 0 | BQ18: =BP18*$B$131 -> 0 | BR18: =$G18*BP18 -> 0 | BT18: =BS18*$B$132 -> 0 | BU18: =$G18*BS18 -> 0 | BW18: =BV18*$B$133 -> 0 | BX18: =$G18*BV18 -> 0 | BZ18: =BY18*$B$134 -> 0 | CA18: =$G18*BY18 -> 0 | CC18: =CB18*$B$135 -> 0 | CD18: =$G18*CB18 -> 0 | CF18: =CE18*$B$136 -> 0 | CG18: =$G18*CE18 -> 0 | CI18: =CH18*$B$137 -> 0 | CJ18: =$G18*CH18 -> 0 | CL18: =CK18*$B$138 -> 0 | CM18: =$G18*CK18 -> 0 | CO18: =CN18*$B$139 -> 0 | CP18: =$G18*CN18 -> 0 | CR18: =CQ18*$B$140 -> 0 | CS18: =$G18*CQ18 -> 0 | CU18: =CT18*$B$141 -> 0 | CV18: =$G18*CT18 -> 0 | CX18: =CW18*$B$142 -> 0 | CY18: =$G18*CW18 -> 0 | DA18: =CZ18*$B$143 -> 0 | DB18: =$G18*CZ18 -> 0 | DD18: =DC18*$B$144 -> 0 | DE18: =$G18*DC18 -> 0 | DG18: =DF18*$B$145 -> 0 | DH18: =$G18*DF18 -> 0 | DJ18: =DI18*$B$146 -> 0 | DK18: =$G18*DI18 -> 0 | DM18: =DL18*$B$147 -> 0 | DN18: =$G18*DL18 -> 0 | DP18: =DO18*$B$148 -> 0 | DQ18: =$G18*DO18 -> 0 | DS18: =DR18*$B$149 -> 0 | DT18: =$G18*DR18 -> 0 | DV18: =DU18*$B$150 -> 0 | DW18: =$G18*DU18 -> 0 | DY18: =DX18*$B$151 -> 0 | DZ18: =$G18*DX18 -> 0 | EB18: =EA18*$B$152 -> 0 | EC18: =$G18*EA18 -> 0 | EE18: =ED18*$B$153 -> 0 | EF18: =$G18*ED18 -> 0 | EH18: =EG18*$B$154 -> 0 | EI18: =$G18*EG18 -> 0 | EK18: =EJ18*$B$155 -> 0 | EL18: =$G18*EJ18 -> 0 | EN18: =EM18*$B$156 -> 0 | EO18: =$G18*EM18 -> 0
A19: 14 | B19: Lock Set | C19: Sargent | D19: 10XG37 -LL | E19: 626 | F19: =SUM(I19,L19,O19,BN19,R19,U19,X19,AA19,BZ19,CC19,CF19,AD19,AG19,AJ19,AM19,AP19,AS19,AV19,AY19,BB19,BE19,BH19,BK19,BQ19,BT19,BW19,CI19,CL19,CO19,CR19,CU19,CX19,DA19,DD19,DG19,DJ19,DM19,DP19,DS19,DV19,DY19,EB19,EE19,EH19,EK19,EN19) -> 2 | I19: =H19*$B$111 -> 0 | J19: =$G19*H19 -> 0 | L19: =K19*$B$112 -> 0 | M19: =$G19*K19 -> 0 | O19: =N19*$B$113 -> 0 | P19: =$G19*N19 -> 0 | R19: =Q19*$B$114 -> 0 | S19: =$G19*Q19 -> 0 | U19: =T19*$B$115 -> 0 | V19: =$G19*T19 -> 0 | X19: =W19*$B$116 -> 0 | Y19: =$G19*W19 -> 0 | AA19: =Z19*$B$117 -> 0 | AB19: =$G19*Z19 -> 0 | AD19: =AC19*$B$118 -> 0 | AE19: =$G19*AC19 -> 0 | AG19: =AF19*$B$119 -> 0 | AH19: =$G19*AF19 -> 0 | AJ19: =AI19*$B$120 -> 0 | AK19: =$G19*AI19 -> 0 | AM19: =AL19*$B$121 -> 0 | AN19: =$G19*AL19 -> 0 | AP19: =AO19*$B$122 -> 0 | AQ19: =$G19*AO19 -> 0 | AS19: =AR19*$B$123 -> 0 | AT19: =$G19*AR19 -> 0 | AV19: =AU19*$B$124 -> 0 | AW19: =$G19*AU19 -> 0 | AY19: =AX19*$B$125 -> 0 | AZ19: =$G19*AX19 -> 0 | BA19: 1 | BB19: =BA19*$B$126 -> 2 | BC19: =$G19*BA19 -> 0 | BE19: =BD19*$B$127 -> 0 | BF19: =$G19*BD19 -> 0 | BH19: =BG19*$B$128 -> 0 | BI19: =$G19*BG19 -> 0 | BK19: =BJ19*$B$129 -> 0 | BL19: =$G19*BJ19 -> 0 | BN19: =BM19*$B$130 -> 0 | BO19: =$G19*BM19 -> 0 | BQ19: =BP19*$B$131 -> 0 | BR19: =$G19*BP19 -> 0 | BT19: =BS19*$B$132 -> 0 | BU19: =$G19*BS19 -> 0 | BW19: =BV19*$B$133 -> 0 | BX19: =$G19*BV19 -> 0 | BZ19: =BY19*$B$134 -> 0 | CA19: =$G19*BY19 -> 0 | CC19: =CB19*$B$135 -> 0 | CD19: =$G19*CB19 -> 0 | CF19: =CE19*$B$136 -> 0 | CG19: =$G19*CE19 -> 0 | CI19: =CH19*$B$137 -> 0 | CJ19: =$G19*CH19 -> 0 | CL19: =CK19*$B$138 -> 0 | CM19: =$G19*CK19 -> 0 | CO19: =CN19*$B$139 -> 0 | CP19: =$G19*CN19 -> 0 | CR19: =CQ19*$B$140 -> 0 | CS19: =$G19*CQ19 -> 0 | CU19: =CT19*$B$141 -> 0 | CV19: =$G19*CT19 -> 0 | CX19: =CW19*$B$142 -> 0 | CY19: =$G19*CW19 -> 0 | DA19: =CZ19*$B$143 -> 0 | DB19: =$G19*CZ19 -> 0 | DD19: =DC19*$B$144 -> 0 | DE19: =$G19*DC19 -> 0 | DG19: =DF19*$B$145 -> 0 | DH19: =$G19*DF19 -> 0 | DJ19: =DI19*$B$146 -> 0 | DK19: =$G19*DI19 -> 0 | DM19: =DL19*$B$147 -> 0 | DN19: =$G19*DL19 -> 0 | DP19: =DO19*$B$148 -> 0 | DQ19: =$G19*DO19 -> 0 | DS19: =DR19*$B$149 -> 0 | DT19: =$G19*DR19 -> 0 | DV19: =DU19*$B$150 -> 0 | DW19: =$G19*DU19 -> 0 | DY19: =DX19*$B$151 -> 0 | DZ19: =$G19*DX19 -> 0 | EB19: =EA19*$B$152 -> 0 | EC19: =$G19*EA19 -> 0 | EE19: =ED19*$B$153 -> 0 | EF19: =$G19*ED19 -> 0 | EH19: =EG19*$B$154 -> 0 | EI19: =$G19*EG19 -> 0 | EK19: =EJ19*$B$155 -> 0 | EL19: =$G19*EJ19 -> 0 | EN19: =EM19*$B$156 -> 0 | EO19: =$G19*EM19 -> 0
A20: 15 | B20: Storeroom Lockset | C20: Sargent | D20: 8204-LC x LNJ x hand | E20: 626 | F20: =SUM(I20,L20,O20,BN20,R20,U20,X20,AA20,BZ20,CC20,CF20,AD20,AG20,AJ20,AM20,AP20,AS20,AV20,AY20,BB20,BE20,BH20,BK20,BQ20,BT20,BW20,CI20,CL20,CO20,CR20,CU20,CX20,DA20,DD20,DG20,DJ20,DM20,DP20,DS20,DV20,DY20,EB20,EE20,EH20,EK20,EN20) -> 2 | I20: =H20*$B$111 -> 0 | J20: =$G20*H20 -> 0 | L20: =K20*$B$112 -> 0 | M20: =$G20*K20 -> 0 | O20: =N20*$B$113 -> 0 | P20: =$G20*N20 -> 0 | R20: =Q20*$B$114 -> 0 | S20: =$G20*Q20 -> 0 | U20: =T20*$B$115 -> 0 | V20: =$G20*T20 -> 0 | X20: =W20*$B$116 -> 0 | Y20: =$G20*W20 -> 0 | AA20: =Z20*$B$117 -> 0 | AB20: =$G20*Z20 -> 0 | AD20: =AC20*$B$118 -> 0 | AE20: =$G20*AC20 -> 0 | AG20: =AF20*$B$119 -> 0 | AH20: =$G20*AF20 -> 0 | AJ20: =AI20*$B$120 -> 0 | AK20: =$G20*AI20 -> 0 | AM20: =AL20*$B$121 -> 0 | AN20: =$G20*AL20 -> 0 | AP20: =AO20*$B$122 -> 0 | AQ20: =$G20*AO20 -> 0 | AS20: =AR20*$B$123 -> 0 | AT20: =$G20*AR20 -> 0 | AV20: =AU20*$B$124 -> 0 | AW20: =$G20*AU20 -> 0 | AY20: =AX20*$B$125 -> 0 | AZ20: =$G20*AX20 -> 0 | BB20: =BA20*$B$126 -> 0 | BC20: =$G20*BA20 -> 0 | BD20: 1 | BE20: =BD20*$B$127 -> 1 | BF20: =$G20*BD20 -> 0 | BG20: 1 | BH20: =BG20*$B$128 -> 1 | BI20: =$G20*BG20 -> 0 | BK20: =BJ20*$B$129 -> 0 | BL20: =$G20*BJ20 -> 0 | BN20: =BM20*$B$130 -> 0 | BO20: =$G20*BM20 -> 0 | BQ20: =BP20*$B$131 -> 0 | BR20: =$G20*BP20 -> 0 | BT20: =BS20*$B$132 -> 0 | BU20: =$G20*BS20 -> 0 | BW20: =BV20*$B$133 -> 0 | BX20: =$G20*BV20 -> 0 | BZ20: =BY20*$B$134 -> 0 | CA20: =$G20*BY20 -> 0 | CC20: =CB20*$B$135 -> 0 | CD20: =$G20*CB20 -> 0 | CF20: =CE20*$B$136 -> 0 | CG20: =$G20*CE20 -> 0 | CI20: =CH20*$B$137 -> 0 | CJ20: =$G20*CH20 -> 0 | CL20: =CK20*$B$138 -> 0 | CM20: =$G20*CK20 -> 0 | CO20: =CN20*$B$139 -> 0 | CP20: =$G20*CN20 -> 0 | CR20: =CQ20*$B$140 -> 0 | CS20: =$G20*CQ20 -> 0 | CU20: =CT20*$B$141 -> 0 | CV20: =$G20*CT20 -> 0 | CX20: =CW20*$B$142 -> 0 | CY20: =$G20*CW20 -> 0 | DA20: =CZ20*$B$143 -> 0 | DB20: =$G20*CZ20 -> 0 | DD20: =DC20*$B$144 -> 0 | DE20: =$G20*DC20 -> 0 | DG20: =DF20*$B$145 -> 0 | DH20: =$G20*DF20 -> 0 | DJ20: =DI20*$B$146 -> 0 | DK20: =$G20*DI20 -> 0 | DM20: =DL20*$B$147 -> 0 | DN20: =$G20*DL20 -> 0 | DP20: =DO20*$B$148 -> 0 | DQ20: =$G20*DO20 -> 0 | DS20: =DR20*$B$149 -> 0 | DT20: =$G20*DR20 -> 0 | DV20: =DU20*$B$150 -> 0 | DW20: =$G20*DU20 -> 0 | DY20: =DX20*$B$151 -> 0 | DZ20: =$G20*DX20 -> 0 | EB20: =EA20*$B$152 -> 0 | EC20: =$G20*EA20 -> 0 | EE20: =ED20*$B$153 -> 0 | EF20: =$G20*ED20 -> 0 | EH20: =EG20*$B$154 -> 0 | EI20: =$G20*EG20 -> 0 | EK20: =EJ20*$B$155 -> 0 | EL20: =$G20*EJ20 -> 0 | EN20: =EM20*$B$156 -> 0 | EO20: =$G20*EM20 -> 0
